Workbook
Name arb_2014: #REF!
Name arb_2014: #REF!
Name ATB_2014: #REF!
Name ATB_2014: #REF!
Name ATB_2015: #REF!
Name ATB_2015: #REF!
Name biek_2015: #REF!
Name biek_2015: #REF!
Name LRA_64: #REF!
Name LRA_64: #REF!
Name No_2020: #REF!
Name No_2020: #REF!
Name non_op: #REF!
Name non_op: #REF!
Name op: #REF!
Name op: #REF!
Name peralatan_dan_Mesin: 'KENDARAAN DINAS'!$A:$AV
Name saldo_arb: #REF!
Name saldo_arb: #REF!
Name saldo_atb: #REF!
Name saldo_atb: #REF!
Name saldo_biek: #REF!
Name saldo_biek: #REF!
Name tanah: 'KIB A - Tanah'!$A:$AT
Name tanah: #REF!

Sheet KENDARAAN DINAS
A2: PEMERINTAH KABUPATEN SERUYAN
A3: KARTU INVENTARIS BARANG (KIB B)
A4: PERALATAN DAN MESIN
A7: Provinsi | C7: : KALIMANTAN TENGAH
A8: Kab./ Kota | C8: : SERUYAN
A9: Bidang | C9: :
A10: Unit Organisasi | C10: :
A11: Sub Unit Organisasi | C11: :
A12: NO. KODE LOKASI | C12: : 12.24.08.15.01.01.01
A14: NO. | B14: Kode | C14: Nama Barang/ | D14: Nomor | E14: Merk/ | F14: Ukuran/ | G14: Bahan | H14: Tahun | N14: Asal usul | P14: Harga | Q14: Keterangan | R14: Pengguna/Pemakai | S14: SKPD
A15: Urut | B15: Barang | C15: Jenis Barang | D15: Register | E15: Type | F15: CC | H15: Pembelian | I15: Pabrik | J15: Rangka | K15: Mesin | L15: Polisi | M15: BPKB
A17: 1 | B17: 02.02.01.01.003 | C17: Station Wagon | D17: 000001 | E17: Toyota Kijang / Toyota Kijang | F17: 1800 cc | G17: Besi | H17: 2002 | J17: NULL | K17: Null | L17: KH 1511 PM | M17: Null | N17: pembelian | O17: 1 | P17: 125000 | S17: DINAS PENDIDIKAN | T17: 1 | U17: 4
A18: 2 | B18: 02.02.01.01.003 | C18: Station Wagon | D18: 000002 | E18: Innova / Innova Zenix 2.0 | F18: 1987 cc | G18: CAMPURAN | H18: 2024 | I18: - | J18: MHFABBAA4R0435901 | K18: M20ANC96961 | L18: KH 1337 PU | M18: V-04726911 | N18: Pembelian | O18: 1 | P18: 638000 | Q18: Belanja Modal Kendaraan Dinas Bermotor Perorangan (Pengadaan Mobil Dinas) | S18: DINAS PENDIDIKAN | T18: 1 | U18: 4
A19: 3 | B19: 02.02.01.03.002 | C19: Pick Up | D19: 000002 | E19: MOBIL Toyota/2 GD FTV, 4 Cylinders / KB-P2209-1600333 HILUX DOUBLE CABIN 2.4. V(4 x 4) | F19: 2,393 cc | G19: CAMPURAN | H19: 2022 | J19: MR0BB3CD8N5810152 | K19: 2GD 5269380 | L19: KH 8214 PW | M19: D 1925403 M | N19: Pembelian | O19: 1 | P19: 504000 | Q19: Belanja modal kendaraan bermotor angkutan barang (Pengadaan kendaraan dinas operasional lapangan) Dinas Pendidikan Kabupaten Seruyan | S19: DINAS PENDIDIKAN | T19: 1 | U19: 4
A20: 4 | B20: 02.02.01.04.001 | C20: Sepeda Motor | D20: 000001 | E20: Honda NF 100 LD / Honda NF 100 LD | F20: 100 | G20: Besi | H20: 2004 | J20: MHIHB21134K283403 | K20: HB21E-1284546 | L20: KH 3077 PM | M20: D 0073191 M | N20: pembelian | O20: 1 | P20: 8000 | S20: DINAS PENDIDIKAN | T20: 1 | U20: 3
A21: 5 | B21: 02.02.01.04.001 | C21: Sepeda Motor | D21: 000001 | E21: Suzuki Suzuki 125 / Suzuki Suzuki 125 | F21: 125 | G21: Besi | H21: 2007 | J21: MH8BF45DA8J-209094 | K21: F496ID-258062 | L21: KH 2528 PY | M21: F 4748855 M | N21: pembelian | O21: 1 | P21: 11250 | S21: DINAS PENDIDIKAN | T21: 1 | U21: 3
A22: 6 | B22: 02.02.01.04.001 | C22: Sepeda Motor | D22: 000002 | E22: Honda NF 100 LD / Honda NF 100 LD | F22: 100 | G22: Besi | H22: 2005 | J22: MHIKIVAE1X4K990626 | K22: KEVAE1992934 | L22: KH 2005 PM | M22: Null | N22: pembelian | O22: 1 | P22: 8000 | S22: DINAS PENDIDIKAN | T22: 1 | U22: 3
A23: 7 | B23: 02.02.01.04.001 | C23: Sepeda Motor | D23: 000003 | E23: Honda NF 100 LD / Honda NF 100 LD | F23: 100 | G23: Besi | H23: 2005 | J23: MHIHB21174K585469 | K23: HB21E-1548243 | L23: KH 3092 PM | M23: Null | N23: pembelian | O23: 1 | P23: 8000 | S23: DINAS PENDIDIKAN | T23: 1 | U23: 3
A24: 8 | B24: 02.02.01.04.001 | C24: Sepeda Motor | D24: 000004 | E24: Honda NF 100 LD / Honda NF 100 LD | F24: 100 | G24: Besi | H24: 2005 | I24: - | J24: MHIHB211X4K579230 | K24: HB21E-1580599 | L24: KH 3093 PM | M24: D 1625432 M | N24: pembelian | O24: 1 | P24: 8000 | S24: DINAS PENDIDIKAN | T24: 1 | U24: 3
A25: 9 | B25: 02.02.01.04.001 | C25: Sepeda Motor | D25: 000005 | E25: Honda NF 125 XD / Honda NF 125 XD | F25: 125 | G25: Besi | H25: 2005 | J25: MHIJB22134K161303 | K25: JB22E-1160588 | L25: KH 3091 PM | M25: Null | N25: pembelian | O25: 1 | P25: 8000 | S25: DINAS PENDIDIKAN | T25: 1 | U25: 3
A26: 10 | B26: 02.02.01.04.001 | C26: Sepeda Motor | D26: 000006 | E26: Honda NF 125 XD / Honda NF 125 XD | F26: 125 | G26: Besi | H26: 2005 | J26: MHIJB22104K168614 | K26: JB22E-1168726 | L26: KH 3094 PM | M26: Null | N26: pembelian | O26: 1 | P26: 8000 | S26: DINAS PENDIDIKAN | T26: 1 | U26: 3
A27: 11 | B27: 02.02.01.04.001 | C27: Sepeda Motor | D27: 000007 | E27: Honda Win MCB / Honda Win MCB | F27: 125 | G27: Besi | H27: 2005 | I27: - | J27: MHIHABD134K088136 | K27: HABD51088987 | L27: KH 2003 PM | M27: 1925136 M | N27: pembelian | O27: 1 | P27: 8000 | S27: DINAS PENDIDIKAN | T27: 1 | U27: 3
A28: 12 | B28: 02.02.01.04.001 | C28: Sepeda Motor | D28: 000010 | E28: Honda NF 100 LD / Honda NF 100 LD | F28: 100 | G28: Besi | H28: 2005 | J28: MHIHB21174K585468 | K28: HB21E-1443783 | L28: KH 3088 PM | M28: Null | N28: pembelian | O28: 1 | P28: 8000 | S28: DINAS PENDIDIKAN | T28: 1 | U28: 3
A29: 13 | B29: 02.02.01.04.001 | C29: Sepeda Motor | D29: 000011 | E29: Honda Win CMB / Honda Win CMB | F29: 125 | G29: Besi | H29: 2005 | J29: MHIHABD124K088147 | K29: HABDE1088993 | L29: KH 2001 PM | M29: Null | N29: pembelian | O29: 1 | P29: 10500 | S29: DINAS PENDIDIKAN | T29: 1 | U29: 3
A30: 14 | B30: 02.02.01.04.001 | C30: Sepeda Motor | D30: 000012 | E30: Yamaha Zupiter Z / Yamaha Zupiter Z | F30: 110 | G30: Besi | H30: 2005 | I30: - | J30: MH35TP0054K326052 | K30: STP525369 | L30: KH 2716 PY | M30: D 1925403 M | N30: pembelian | O30: 1 | P30: 14000 | S30: DINAS PENDIDIKAN | T30: 1 | U30: 3
A31: 15 | B31: 02.02.01.04.001 | C31: Sepeda Motor | D31: 000013 | E31: HONDA VARIO TECHO CBS / HONDA VARIO TECHO CBS | F31: 124.8 | G31: BESI | H31: 2014 | J31: MH1JFJ119EK338230 | K31: JFJ1E1334255 | L31: KH 4326 PY | M31: L 04350939 M | N31: pembelian | O31: 1 | P31: 17194 | Q31: ARITA /DPRD | S31: DINAS PENDIDIKAN | T31: 1 | U31: 3
A32: 16 | B32: 02.02.01.04.001 | C32: Sepeda Motor | D32: 000014 | E32: HONDA VERZA 150 CW-2015 / HONDA VERZA 150 CW-2015 | F32: 149 | G32: BESI | H32: 2015 | J32: MH1KC5217FK255089 | K32: KC52E-1252761 | L32: KH 4344 PY | M32: L 06930513 M | N32: pembelian | O32: 1 | P32: 19430 | Q32: DINAS PENDIDIKAN | S32: DINAS PENDIDIKAN | T32: 1 | U32: 3
A33: 17 | B33: 02.02.01.04.001 | C33: Sepeda Motor | D33: 000015 | E33: HONDA Y1G02N02L0 A/T / HONDA Y1G02N02L0 A/T | F33: 108 CC | G33: BESI | H33: 2017 | I33: - | J33: MH1JFS119HK398373 | K33: JFS1E1390127 | L33: KH 4650 PY | M33: M 12824308 M | N33: pembelian | O33: 1 | P33: 15252.264 | Q33: DINAS PENDIDIKAN | S33: DINAS PENDIDIKAN | T33: 1 | U33: 3
A34: 18 | B34: 02.02.01.04.001 | C34: Sepeda Motor | D34: 000016 | E34: HONDA NEW BEAT SPORTY CW 2018 D1B02N26L2 A/T / HONDA NEW BEAT SPORTY CW 2018 D1B02N26L2 A/T | F34: 108 | G34: BESI | H34: 2018 | I34: - | J34: MH1JFZ123JK859588 | K34: JFZ1E2857112 | L34: KH 4790 PY | M34: O02643660M | N34: pembelian | O34: 1 | P34: 15534 | Q34: Mutasi | S34: DINAS PENDIDIKAN | T34: 1 | U34: 3
A35: 19 | B35: 02.02.01.04.001 | C35: Sepeda Motor | D35: 000017 | E35: Suzuki RR FL 125 RCD / Suzuki RR FL 125 RCD | F35: 125 cc | G35: Besi | H35: 2008 | J35: MH8BF45DA8J208900 | K35: F496 - ID - 257880 | L35: KH 2526 PY | M35: F 4847854 M | N35: pembelian | O35: 1 | P35: 15000 | S35: DINAS PENDIDIKAN | T35: 1 | U35: 3
A36: 20 | B36: 02.02.01.04.001 | C36: Sepeda Motor | D36: 000018 | E36: Suzuki RR FL 125 RCD / Suzuki RR FL 125 RCD | F36: 125 cc | G36: Besi | H36: 2008 | J36: MH8BF45DA8J209130 | K36: F496 - ID - 258038 | L36: KH 2521 PY | M36: F 4847850 M | N36: pembelian | O36: 1 | P36: 15000 | S36: DINAS PENDIDIKAN | T36: 1 | U36: 3
A37: 21 | B37: 02.02.01.04.001 | C37: Sepeda Motor | D37: 000020 | E37: Suzuki RR FL 125 RCD / Suzuki RR FL 125 RCD | F37: 125 cc | G37: Besi | H37: 2008 | J37: MH8BF45DA8J209136 | K37: F496 - ID - 258046 | L37: KH 2519 PY | M37: F 4847848 M | N37: pembelian | O37: 1 | P37: 15000 | S37: DINAS PENDIDIKAN | T37: 1 | U37: 3
A38: 22 | B38: 02.02.01.04.001 | C38: Sepeda Motor | D38: 000021 | E38: Suzuki RR FL 125 RCD / Suzuki RR FL 125 RCD | F38: 125 cc | G38: Besi | H38: 2008 | J38: MH8BF45DA8J209094 | K38: F496 - ID - 258062 | L38: KH 2528 PY | M38: F 4748855 M | N38: pembelian | O38: 1 | P38: 15000 | S38: DINAS PENDIDIKAN | T38: 1 | U38: 3
A39: 23 | B39: 02.02.01.04.001 | C39: Sepeda Motor | D39: 000022 | E39: Suzuki / Suzuki | F39: 125 | G39: Besi | H39: 2008 | J39: MH8BF45DA8J208900 | K39: F496 - ID - 257880 | L39: KH 2526 PY | M39: F 4847854 M | N39: pembelian | O39: 1 | P39: 16950 | S39: DINAS PENDIDIKAN | T39: 1 | U39: 3
A40: 24 | B40: 02.02.01.04.001 | C40: Sepeda Motor | D40: 000023 | E40: Suzuki / Suzuki | F40: 125 | G40: Besi | H40: 2008 | J40: MH8BF45DA8J209130 | K40: F496 - ID - 258038 | L40: KH 2521 PY | M40: F 4847850 M | N40: pembelian | O40: 1 | P40: 16950 | S40: DINAS PENDIDIKAN | T40: 1 | U40: 3
A41: 25 | B41: 02.02.01.04.001 | C41: Sepeda Motor | D41: 000024 | E41: Suzuki / Suzuki | F41: 125 | G41: Besi | H41: 2008 | J41: MH8BF45DA8J209094 | K41: F496 - ID - 258062 | L41: KH 2528 PY | M41: F 4748855 M | N41: pembelian | O41: 1 | P41: 16950 | S41: DINAS PENDIDIKAN | T41: 1 | U41: 3
A42: 26 | B42: 02.02.01.04.001 | C42: Sepeda Motor | D42: 000025 | E42: Suzuki / Suzuki | F42: 125 | G42: Besi | H42: 2008 | J42: MH8BF45DA8J207974 | K42: F496 - ID - 257087 | L42: KH 2524 PY | M42: Null | N42: pembelian | O42: 1 | P42: 16950 | S42: DINAS PENDIDIKAN | T42: 1 | U42: 3
A43: 27 | B43: 02.02.01.04.001 | C43: Sepeda Motor | D43: 000026 | E43: Suzuki / Suzuki | F43: 110 | G43: Besi | H43: 2008 | J43: MH8BF45DA8J209136 | K43: F496 - ID - 258046 | L43: KH 2519 PY | M43: F 4847848 M | N43: pembelian | O43: 1 | P43: 16950 | S43: DINAS PENDIDIKAN | T43: 1 | U43: 3
A44: 28 | B44: 02.02.01.04.001 | C44: Sepeda Motor | D44: 000027 | E44: HONDA NF 11 B2D1 M/T Revo FIT / HONDA NF 11 B2D1 M/T Revo FIT | F44: 110 CC | G44: Besi | H44: 2012 | J44: MH1JBE110CK409380 | K44: JBE1E1401386 | L44: KH 4085 PY | M44: I-10731509 M | N44: pembelian | O44: 1 | P44: 12577.55 | Q44: Disdikpora / UPTD. Seruyan Hulu | S44: DINAS PENDIDIKAN | T44: 1 | U44: 3
A45: 29 | B45: 02.02.01.04.001 | C45: Sepeda Motor | D45: 000028 | E45: HONDA NF 11 B2D1 M/T Revo FIT / HONDA NF 11 B2D1 M/T Revo FIT | F45: 110 CC | G45: Besi | H45: 2012 | J45: MH1JBE114CK417126 | K45: JBE1E1402249 | L45: KH 4089 PY | M45: I-10731513 M | N45: pembelian | O45: 1 | P45: 12577.55 | Q45: Disdikpora / UPTD. Suling Tambun | S45: DINAS PENDIDIKAN | T45: 1 | U45: 3
...

Sheet REKAP KENDARAAN DINAS
A1: NO | B1: NAMA SKPD | C1: SEPEDA MOTOR | E1: MOBIL | G1: BUS | I1: TRUK | K1: ALAT BERAT | M1: TRAKTOR | O1: JUMLAH TOTAL
C2: JUMLAH | D2: NILAI PEROLEHAN | E2: JUMLAH | F2: NILAI PEROLEHAN | G2: JUMLAH | H2: NILAI PEROLEHAN | I2: JUMLAH | J2: NILAI PEROLEHAN | K2: JUMLAH | L2: NILAI PEROLEHAN | M2: JUMLAH | N2: NILAI PEROLEHAN | O2: JUMLAH | P2: NILAI PEROLEHAN
A3: 1 | B3: 2 | C3: 3 | E3: 4 | G3: 5 | I3: 6 | K3: 7 | M3: 8 | P3: 9
A4: 1 | B4: DINAS PENDIDIKAN | C4: =SUMIFS('KENDARAAN DINAS'!$O:$O,'KENDARAAN DINAS'!$U:$U,'REKAP KENDARAAN DINAS'!$C$3,'KENDARAAN DINAS'!$T:$T,'REKAP KENDARAAN DINAS'!A4) -> 60 | D4: =SUMIFS('KENDARAAN DINAS'!$P:$P,'KENDARAAN DINAS'!$U:$U,'REKAP KENDARAAN DINAS'!$C$3,'KENDARAAN DINAS'!$T:$T,A4) -> 1163805 | E4: =SUMIFS('KENDARAAN DINAS'!$O:$O,'KENDARAAN DINAS'!$U:$U,$E$3,'KENDARAAN DINAS'!$T:$T,A4) -> 3 | F4: =SUMIFS('KENDARAAN DINAS'!$P:$P,'KENDARAAN DINAS'!$U:$U,$E$3,'KENDARAAN DINAS'!$T:$T,A4) -> 1267000 | G4: =SUMIFS('KENDARAAN DINAS'!$O:$O,'KENDARAAN DINAS'!$U:$U,$G$3,'KENDARAAN DINAS'!$T:$T,A4) -> 0 | H4: =SUMIFS('KENDARAAN DINAS'!$P:$P,'KENDARAAN DINAS'!$U:$U,$G$3,'KENDARAAN DINAS'!$T:$T,A4) -> 0 | I4: =SUMIFS('KENDARAAN DINAS'!$O:$O,'KENDARAAN DINAS'!$U:$U,$I$3,'KENDARAAN DINAS'!$T:$T,A4) -> 0 | J4: =SUMIFS('KENDARAAN DINAS'!$P:$P,'KENDARAAN DINAS'!$U:$U,$I$3,'KENDARAAN DINAS'!$T:$T,A4) -> 0 | K4: =SUMIFS('KENDARAAN DINAS'!$O:$O,'KENDARAAN DINAS'!$U:$U,$K$3,'KENDARAAN DINAS'!$T:$T,A4) -> 0 | L4: =SUMIFS('KENDARAAN DINAS'!$P:$P,'KENDARAAN DINAS'!$U:$U,$K$3,'KENDARAAN DINAS'!$T:$T,A5) -> 0 | M4: =SUMIFS('KENDARAAN DINAS'!$O:$O,'KENDARAAN DINAS'!$U:$U,$M$3,'KENDARAAN DINAS'!$T:$T,A4) -> 0 | N4: =SUMIFS('KENDARAAN DINAS'!$P:$P,'KENDARAAN DINAS'!$U:$U,$M$3,'KENDARAAN DINAS'!$T:$T,A4) -> 0 | O4: =C4+E4+G4+I4+K4+M4 -> 63 | P4: =D4+F4+H4+J4+L4+N4 -> 2430805
A5: 2 | B5: DINAS KESEHATAN | C5: =SUMIFS('KENDARAAN DINAS'!$O:$O,'KENDARAAN DINAS'!$U:$U,'REKAP KENDARAAN DINAS'!$C$3,'KENDARAAN DINAS'!$T:$T,'REKAP KENDARAAN DINAS'!A5) -> 215 | D5: =SUMIFS('KENDARAAN DINAS'!$P:$P,'KENDARAAN DINAS'!$U:$U,'REKAP KENDARAAN DINAS'!$C$3,'KENDARAAN DINAS'!$T:$T,A5) -> 3547025.1 | E5: =SUMIFS('KENDARAAN DINAS'!$O:$O,'KENDARAAN DINAS'!$U:$U,$E$3,'KENDARAAN DINAS'!$T:$T,A5) -> 33 | F5: =SUMIFS('KENDARAAN DINAS'!$P:$P,'KENDARAAN DINAS'!$U:$U,$E$3,'KENDARAAN DINAS'!$T:$T,A5) -> 11445354 | G5: =SUMIFS('KENDARAAN DINAS'!$O:$O,'KENDARAAN DINAS'!$U:$U,$G$3,'KENDARAAN DINAS'!$T:$T,A5) -> 0 | H5: =SUMIFS('KENDARAAN DINAS'!$P:$P,'KENDARAAN DINAS'!$U:$U,$G$3,'KENDARAAN DINAS'!$T:$T,A5) -> 0 | I5: =SUMIFS('KENDARAAN DINAS'!$O:$O,'KENDARAAN DINAS'!$U:$U,$I$3,'KENDARAAN DINAS'!$T:$T,A5) -> 1 | J5: =SUMIFS('KENDARAAN DINAS'!$P:$P,'KENDARAAN DINAS'!$U:$U,$I$3,'KENDARAAN DINAS'!$T:$T,A5) -> 643500 | K5: =SUMIFS('KENDARAAN DINAS'!$O:$O,'KENDARAAN DINAS'!$U:$U,$K$3,'KENDARAAN DINAS'!$T:$T,A5) -> 0 | L5: =SUMIFS('KENDARAAN DINAS'!$P:$P,'KENDARAAN DINAS'!$U:$U,$K$3,'KENDARAAN DINAS'!$T:$T,A6) -> 0 | M5: =SUMIFS('KENDARAAN DINAS'!$O:$O,'KENDARAAN DINAS'!$U:$U,$M$3,'KENDARAAN DINAS'!$T:$T,A5) -> 0 | N5: =SUMIFS('KENDARAAN DINAS'!$P:$P,'KENDARAAN DINAS'!$U:$U,$M$3,'KENDARAAN DINAS'!$T:$T,A5) -> 0 | O5: =C5+E5+G5+I5+K5+M5 -> 249 | P5: =D5+F5+H5+J5+L5+N5 -> 15635879
A6: 3 | B6: RUMAH SAKIT UMUM DAERAH | C6: =SUMIFS('KENDARAAN DINAS'!$O:$O,'KENDARAAN DINAS'!$U:$U,'REKAP KENDARAAN DINAS'!$C$3,'KENDARAAN DINAS'!$T:$T,'REKAP KENDARAAN DINAS'!A6) -> 13 | D6: =SUMIFS('KENDARAAN DINAS'!$P:$P,'KENDARAAN DINAS'!$U:$U,'REKAP KENDARAAN DINAS'!$C$3,'KENDARAAN DINAS'!$T:$T,A6) -> 188563.57 | E6: =SUMIFS('KENDARAAN DINAS'!$O:$O,'KENDARAAN DINAS'!$U:$U,$E$3,'KENDARAAN DINAS'!$T:$T,A6) -> 20 | F6: =SUMIFS('KENDARAAN DINAS'!$P:$P,'KENDARAAN DINAS'!$U:$U,$E$3,'KENDARAAN DINAS'!$T:$T,A6) -> 4414557.8 | G6: =SUMIFS('KENDARAAN DINAS'!$O:$O,'KENDARAAN DINAS'!$U:$U,$G$3,'KENDARAAN DINAS'!$T:$T,A6) -> 0 | H6: =SUMIFS('KENDARAAN DINAS'!$P:$P,'KENDARAAN DINAS'!$U:$U,$G$3,'KENDARAAN DINAS'!$T:$T,A6) -> 0 | I6: =SUMIFS('KENDARAAN DINAS'!$O:$O,'KENDARAAN DINAS'!$U:$U,$I$3,'KENDARAAN DINAS'!$T:$T,A6) -> 0 | J6: =SUMIFS('KENDARAAN DINAS'!$P:$P,'KENDARAAN DINAS'!$U:$U,$I$3,'KENDARAAN DINAS'!$T:$T,A6) -> 0 | K6: =SUMIFS('KENDARAAN DINAS'!$O:$O,'KENDARAAN DINAS'!$U:$U,$K$3,'KENDARAAN DINAS'!$T:$T,A6) -> 0 | L6: =SUMIFS('KENDARAAN DINAS'!$P:$P,'KENDARAAN DINAS'!$U:$U,$K$3,'KENDARAAN DINAS'!$T:$T,A7) -> 0 | M6: =SUMIFS('KENDARAAN DINAS'!$O:$O,'KENDARAAN DINAS'!$U:$U,$M$3,'KENDARAAN DINAS'!$T:$T,A6) -> 0 | N6: =SUMIFS('KENDARAAN DINAS'!$P:$P,'KENDARAAN DINAS'!$U:$U,$M$3,'KENDARAAN DINAS'!$T:$T,A6) -> 0 | O6: =C6+E6+G6+I6+K6+M6 -> 33 | P6: =D6+F6+H6+J6+L6+N6 -> 4603121.3
A7: 4 | B7: BLUD RUMAH SAKIT UMUM DAERAH KUALA PEMBUANG | C7: =SUMIFS('KENDARAAN DINAS'!$O:$O,'KENDARAAN DINAS'!$U:$U,'REKAP KENDARAAN DINAS'!$C$3,'KENDARAAN DINAS'!$T:$T,'REKAP KENDARAAN DINAS'!A7) -> 15 | D7: =SUMIFS('KENDARAAN DINAS'!$P:$P,'KENDARAAN DINAS'!$U:$U,'REKAP KENDARAAN DINAS'!$C$3,'KENDARAAN DINAS'!$T:$T,A7) -> 327325 | E7: =SUMIFS('KENDARAAN DINAS'!$O:$O,'KENDARAAN DINAS'!$U:$U,$E$3,'KENDARAAN DINAS'!$T:$T,A7) -> 2 | F7: =SUMIFS('KENDARAAN DINAS'!$P:$P,'KENDARAAN DINAS'!$U:$U,$E$3,'KENDARAAN DINAS'!$T:$T,A7) -> 927000 | G7: =SUMIFS('KENDARAAN DINAS'!$O:$O,'KENDARAAN DINAS'!$U:$U,$G$3,'KENDARAAN DINAS'!$T:$T,A7) -> 0 | H7: =SUMIFS('KENDARAAN DINAS'!$P:$P,'KENDARAAN DINAS'!$U:$U,$G$3,'KENDARAAN DINAS'!$T:$T,A7) -> 0 | I7: =SUMIFS('KENDARAAN DINAS'!$O:$O,'KENDARAAN DINAS'!$U:$U,$I$3,'KENDARAAN DINAS'!$T:$T,A7) -> 0 | J7: =SUMIFS('KENDARAAN DINAS'!$P:$P,'KENDARAAN DINAS'!$U:$U,$I$3,'KENDARAAN DINAS'!$T:$T,A7) -> 0 | K7: =SUMIFS('KENDARAAN DINAS'!$O:$O,'KENDARAAN DINAS'!$U:$U,$K$3,'KENDARAAN DINAS'!$T:$T,A7) -> 0 | L7: =SUMIFS('KENDARAAN DINAS'!$P:$P,'KENDARAAN DINAS'!$U:$U,$K$3,'KENDARAAN DINAS'!$T:$T,A8) -> 0 | M7: =SUMIFS('KENDARAAN DINAS'!$O:$O,'KENDARAAN DINAS'!$U:$U,$M$3,'KENDARAAN DINAS'!$T:$T,A7) -> 0 | N7: =SUMIFS('KENDARAAN DINAS'!$P:$P,'KENDARAAN DINAS'!$U:$U,$M$3,'KENDARAAN DINAS'!$T:$T,A7) -> 0 | O7: =C7+E7+G7+I7+K7+M7 -> 17 | P7: =D7+F7+H7+J7+L7+N7 -> 1254325
A8: 5 | B8: DINAS PEKERJAAN UMUM DAN PENATAAN RUANG | C8: =SUMIFS('KENDARAAN DINAS'!$O:$O,'KENDARAAN DINAS'!$U:$U,'REKAP KENDARAAN DINAS'!$C$3,'KENDARAAN DINAS'!$T:$T,'REKAP KENDARAAN DINAS'!A8) -> 40 | D8: =SUMIFS('KENDARAAN DINAS'!$P:$P,'KENDARAAN DINAS'!$U:$U,'REKAP KENDARAAN DINAS'!$C$3,'KENDARAAN DINAS'!$T:$T,A8) -> 1670594.5 | E8: =SUMIFS('KENDARAAN DINAS'!$O:$O,'KENDARAAN DINAS'!$U:$U,$E$3,'KENDARAAN DINAS'!$T:$T,A8) -> 7 | F8: =SUMIFS('KENDARAAN DINAS'!$P:$P,'KENDARAAN DINAS'!$U:$U,$E$3,'KENDARAAN DINAS'!$T:$T,A8) -> 3173510 | G8: =SUMIFS('KENDARAAN DINAS'!$O:$O,'KENDARAAN DINAS'!$U:$U,$G$3,'KENDARAAN DINAS'!$T:$T,A8) -> 0 | H8: =SUMIFS('KENDARAAN DINAS'!$P:$P,'KENDARAAN DINAS'!$U:$U,$G$3,'KENDARAAN DINAS'!$T:$T,A8) -> 0 | I8: =SUMIFS('KENDARAAN DINAS'!$O:$O,'KENDARAAN DINAS'!$U:$U,$I$3,'KENDARAAN DINAS'!$T:$T,A8) -> 12 | J8: =SUMIFS('KENDARAAN DINAS'!$P:$P,'KENDARAAN DINAS'!$U:$U,$I$3,'KENDARAAN DINAS'!$T:$T,A8) -> 7635264 | K8: =SUMIFS('KENDARAAN DINAS'!$O:$O,'KENDARAAN DINAS'!$U:$U,$K$3,'KENDARAAN DINAS'!$T:$T,A8) -> 0 | L8: =SUMIFS('KENDARAAN DINAS'!$P:$P,'KENDARAAN DINAS'!$U:$U,$K$3,'KENDARAAN DINAS'!$T:$T,A9) -> 0 | M8: =SUMIFS('KENDARAAN DINAS'!$O:$O,'KENDARAAN DINAS'!$U:$U,$M$3,'KENDARAAN DINAS'!$T:$T,A8) -> 0 | N8: =SUMIFS('KENDARAAN DINAS'!$P:$P,'KENDARAAN DINAS'!$U:$U,$M$3,'KENDARAAN DINAS'!$T:$T,A8) -> 0 | O8: =C8+E8+G8+I8+K8+M8 -> 59 | P8: =D8+F8+H8+J8+L8+N8 -> 12479369
A9: 6 | B9: DINAS PERUMAHAN RAKYAT DAN KAWASAN PEMUKIMAN | C9: =SUMIFS('KENDARAAN DINAS'!$O:$O,'KENDARAAN DINAS'!$U:$U,'REKAP KENDARAAN DINAS'!$C$3,'KENDARAAN DINAS'!$T:$T,'REKAP KENDARAAN DINAS'!A9) -> 24 | D9: =SUMIFS('KENDARAAN DINAS'!$P:$P,'KENDARAAN DINAS'!$U:$U,'REKAP KENDARAAN DINAS'!$C$3,'KENDARAAN DINAS'!$T:$T,A9) -> 565149.33 | E9: =SUMIFS('KENDARAAN DINAS'!$O:$O,'KENDARAAN DINAS'!$U:$U,$E$3,'KENDARAAN DINAS'!$T:$T,A9) -> 2 | F9: =SUMIFS('KENDARAAN DINAS'!$P:$P,'KENDARAAN DINAS'!$U:$U,$E$3,'KENDARAAN DINAS'!$T:$T,A9) -> 744200 | G9: =SUMIFS('KENDARAAN DINAS'!$O:$O,'KENDARAAN DINAS'!$U:$U,$G$3,'KENDARAAN DINAS'!$T:$T,A9) -> 0 | H9: =SUMIFS('KENDARAAN DINAS'!$P:$P,'KENDARAAN DINAS'!$U:$U,$G$3,'KENDARAAN DINAS'!$T:$T,A9) -> 0 | I9: =SUMIFS('KENDARAAN DINAS'!$O:$O,'KENDARAAN DINAS'!$U:$U,$I$3,'KENDARAAN DINAS'!$T:$T,A9) -> 0 | J9: =SUMIFS('KENDARAAN DINAS'!$P:$P,'KENDARAAN DINAS'!$U:$U,$I$3,'KENDARAAN DINAS'!$T:$T,A9) -> 0 | K9: =SUMIFS('KENDARAAN DINAS'!$O:$O,'KENDARAAN DINAS'!$U:$U,$K$3,'KENDARAAN DINAS'!$T:$T,A9) -> 0 | L9: =SUMIFS('KENDARAAN DINAS'!$P:$P,'KENDARAAN DINAS'!$U:$U,$K$3,'KENDARAAN DINAS'!$T:$T,A10) -> 0 | M9: =SUMIFS('KENDARAAN DINAS'!$O:$O,'KENDARAAN DINAS'!$U:$U,$M$3,'KENDARAAN DINAS'!$T:$T,A9) -> 0 | N9: =SUMIFS('KENDARAAN DINAS'!$P:$P,'KENDARAAN DINAS'!$U:$U,$M$3,'KENDARAAN DINAS'!$T:$T,A9) -> 0 | O9: =C9+E9+G9+I9+K9+M9 -> 26 | P9: =D9+F9+H9+J9+L9+N9 -> 1309349.3
A10: 7 | B10: SATUAN POLISI PAMONG PRAJA DAN PEMADAM KEBAKARAN | C10: =SUMIFS('KENDARAAN DINAS'!$O:$O,'KENDARAAN DINAS'!$U:$U,'REKAP KENDARAAN DINAS'!$C$3,'KENDARAAN DINAS'!$T:$T,'REKAP KENDARAAN DINAS'!A10) -> 8 | D10: =SUMIFS('KENDARAAN DINAS'!$P:$P,'KENDARAAN DINAS'!$U:$U,'REKAP KENDARAAN DINAS'!$C$3,'KENDARAAN DINAS'!$T:$T,A10) -> 218588 | E10: =SUMIFS('KENDARAAN DINAS'!$O:$O,'KENDARAAN DINAS'!$U:$U,$E$3,'KENDARAAN DINAS'!$T:$T,A10) -> 4 | F10: =SUMIFS('KENDARAAN DINAS'!$P:$P,'KENDARAAN DINAS'!$U:$U,$E$3,'KENDARAAN DINAS'!$T:$T,A10) -> 1406720 | G10: =SUMIFS('KENDARAAN DINAS'!$O:$O,'KENDARAAN DINAS'!$U:$U,$G$3,'KENDARAAN DINAS'!$T:$T,A10) -> 0 | H10: =SUMIFS('KENDARAAN DINAS'!$P:$P,'KENDARAAN DINAS'!$U:$U,$G$3,'KENDARAAN DINAS'!$T:$T,A10) -> 0 | I10: =SUMIFS('KENDARAAN DINAS'!$O:$O,'KENDARAAN DINAS'!$U:$U,$I$3,'KENDARAAN DINAS'!$T:$T,A10) -> 1 | J10: =SUMIFS('KENDARAAN DINAS'!$P:$P,'KENDARAAN DINAS'!$U:$U,$I$3,'KENDARAAN DINAS'!$T:$T,A10) -> 358291 | K10: =SUMIFS('KENDARAAN DINAS'!$O:$O,'KENDARAAN DINAS'!$U:$U,$K$3,'KENDARAAN DINAS'!$T:$T,A10) -> 0 | L10: =SUMIFS('KENDARAAN DINAS'!$P:$P,'KENDARAAN DINAS'!$U:$U,$K$3,'KENDARAAN DINAS'!$T:$T,A11) -> 0 | M10: =SUMIFS('KENDARAAN DINAS'!$O:$O,'KENDARAAN DINAS'!$U:$U,$M$3,'KENDARAAN DINAS'!$T:$T,A10) -> 0 | N10: =SUMIFS('KENDARAAN DINAS'!$P:$P,'KENDARAAN DINAS'!$U:$U,$M$3,'KENDARAAN DINAS'!$T:$T,A10) -> 0 | O10: =C10+E10+G10+I10+K10+M10 -> 13 | P10: =D10+F10+H10+J10+L10+N10 -> 1983599
A11: 8 | B11: BADAN KESATUAN BANGSA DAN POLITIK | C11: =SUMIFS('KENDARAAN DINAS'!$O:$O,'KENDARAAN DINAS'!$U:$U,'REKAP KENDARAAN DINAS'!$C$3,'KENDARAAN DINAS'!$T:$T,'REKAP KENDARAAN DINAS'!A11) -> 9 | D11: =SUMIFS('KENDARAAN DINAS'!$P:$P,'KENDARAAN DINAS'!$U:$U,'REKAP KENDARAAN DINAS'!$C$3,'KENDARAAN DINAS'!$T:$T,A11) -> 167628.3 | E11: =SUMIFS('KENDARAAN DINAS'!$O:$O,'KENDARAAN DINAS'!$U:$U,$E$3,'KENDARAAN DINAS'!$T:$T,A11) -> 2 | F11: =SUMIFS('KENDARAAN DINAS'!$P:$P,'KENDARAAN DINAS'!$U:$U,$E$3,'KENDARAAN DINAS'!$T:$T,A11) -> 532945 | G11: =SUMIFS('KENDARAAN DINAS'!$O:$O,'KENDARAAN DINAS'!$U:$U,$G$3,'KENDARAAN DINAS'!$T:$T,A11) -> 0 | H11: =SUMIFS('KENDARAAN DINAS'!$P:$P,'KENDARAAN DINAS'!$U:$U,$G$3,'KENDARAAN DINAS'!$T:$T,A11) -> 0 | I11: =SUMIFS('KENDARAAN DINAS'!$O:$O,'KENDARAAN DINAS'!$U:$U,$I$3,'KENDARAAN DINAS'!$T:$T,A11) -> 0 | J11: =SUMIFS('KENDARAAN DINAS'!$P:$P,'KENDARAAN DINAS'!$U:$U,$I$3,'KENDARAAN DINAS'!$T:$T,A11) -> 0 | K11: =SUMIFS('KENDARAAN DINAS'!$O:$O,'KENDARAAN DINAS'!$U:$U,$K$3,'KENDARAAN DINAS'!$T:$T,A11) -> 0 | L11: =SUMIFS('KENDARAAN DINAS'!$P:$P,'KENDARAAN DINAS'!$U:$U,$K$3,'KENDARAAN DINAS'!$T:$T,A12) -> 0 | M11: =SUMIFS('KENDARAAN DINAS'!$O:$O,'KENDARAAN DINAS'!$U:$U,$M$3,'KENDARAAN DINAS'!$T:$T,A11) -> 0 | N11: =SUMIFS('KENDARAAN DINAS'!$P:$P,'KENDARAAN DINAS'!$U:$U,$M$3,'KENDARAAN DINAS'!$T:$T,A11) -> 0 | O11: =C11+E11+G11+I11+K11+M11 -> 11 | P11: =D11+F11+H11+J11+L11+N11 -> 700573.3
A12: 9 | B12: DINAS SOSIAL | C12: =SUMIFS('KENDARAAN DINAS'!$O:$O,'KENDARAAN DINAS'!$U:$U,'REKAP KENDARAAN DINAS'!$C$3,'KENDARAAN DINAS'!$T:$T,'REKAP KENDARAAN DINAS'!A12) -> 10 | D12: =SUMIFS('KENDARAAN DINAS'!$P:$P,'KENDARAAN DINAS'!$U:$U,'REKAP KENDARAAN DINAS'!$C$3,'KENDARAAN DINAS'!$T:$T,A12) -> 178791.6 | E12: =SUMIFS('KENDARAAN DINAS'!$O:$O,'KENDARAAN DINAS'!$U:$U,$E$3,'KENDARAAN DINAS'!$T:$T,A12) -> 3 | F12: =SUMIFS('KENDARAAN DINAS'!$P:$P,'KENDARAAN DINAS'!$U:$U,$E$3,'KENDARAAN DINAS'!$T:$T,A12) -> 1163270 | G12: =SUMIFS('KENDARAAN DINAS'!$O:$O,'KENDARAAN DINAS'!$U:$U,$G$3,'KENDARAAN DINAS'!$T:$T,A12) -> 0 | H12: =SUMIFS('KENDARAAN DINAS'!$P:$P,'KENDARAAN DINAS'!$U:$U,$G$3,'KENDARAAN DINAS'!$T:$T,A12) -> 0 | I12: =SUMIFS('KENDARAAN DINAS'!$O:$O,'KENDARAAN DINAS'!$U:$U,$I$3,'KENDARAAN DINAS'!$T:$T,A12) -> 0 | J12: =SUMIFS('KENDARAAN DINAS'!$P:$P,'KENDARAAN DINAS'!$U:$U,$I$3,'KENDARAAN DINAS'!$T:$T,A12) -> 0 | K12: =SUMIFS('KENDARAAN DINAS'!$O:$O,'KENDARAAN DINAS'!$U:$U,$K$3,'KENDARAAN DINAS'!$T:$T,A12) -> 0 | L12: =SUMIFS('KENDARAAN DINAS'!$P:$P,'KENDARAAN DINAS'!$U:$U,$K$3,'KENDARAAN DINAS'!$T:$T,A13) -> 0 | M12: =SUMIFS('KENDARAAN DINAS'!$O:$O,'KENDARAAN DINAS'!$U:$U,$M$3,'KENDARAAN DINAS'!$T:$T,A12) -> 0 | N12: =SUMIFS('KENDARAAN DINAS'!$P:$P,'KENDARAAN DINAS'!$U:$U,$M$3,'KENDARAAN DINAS'!$T:$T,A12) -> 0 | O12: =C12+E12+G12+I12+K12+M12 -> 13 | P12: =D12+F12+H12+J12+L12+N12 -> 1342061.6
A13: 10 | B13: DINAS TENAGA KERJA DAN TRANSMIGRASI | C13: =SUMIFS('KENDARAAN DINAS'!$O:$O,'KENDARAAN DINAS'!$U:$U,'REKAP KENDARAAN DINAS'!$C$3,'KENDARAAN DINAS'!$T:$T,'REKAP KENDARAAN DINAS'!A13) -> 13 | D13: =SUMIFS('KENDARAAN DINAS'!$P:$P,'KENDARAAN DINAS'!$U:$U,'REKAP KENDARAAN DINAS'!$C$3,'KENDARAAN DINAS'!$T:$T,A13) -> 213429.98 | E13: =SUMIFS('KENDARAAN DINAS'!$O:$O,'KENDARAAN DINAS'!$U:$U,$E$3,'KENDARAAN DINAS'!$T:$T,A13) -> 2 | F13: =SUMIFS('KENDARAAN DINAS'!$P:$P,'KENDARAAN DINAS'!$U:$U,$E$3,'KENDARAAN DINAS'!$T:$T,A13) -> 472787.2 | G13: =SUMIFS('KENDARAAN DINAS'!$O:$O,'KENDARAAN DINAS'!$U:$U,$G$3,'KENDARAAN DINAS'!$T:$T,A13) -> 0 | H13: =SUMIFS('KENDARAAN DINAS'!$P:$P,'KENDARAAN DINAS'!$U:$U,$G$3,'KENDARAAN DINAS'!$T:$T,A13) -> 0 | I13: =SUMIFS('KENDARAAN DINAS'!$O:$O,'KENDARAAN DINAS'!$U:$U,$I$3,'KENDARAAN DINAS'!$T:$T,A13) -> 0 | J13: =SUMIFS('KENDARAAN DINAS'!$P:$P,'KENDARAAN DINAS'!$U:$U,$I$3,'KENDARAAN DINAS'!$T:$T,A13) -> 0 | K13: =SUMIFS('KENDARAAN DINAS'!$O:$O,'KENDARAAN DINAS'!$U:$U,$K$3,'KENDARAAN DINAS'!$T:$T,A13) -> 0 | L13: =SUMIFS('KENDARAAN DINAS'!$P:$P,'KENDARAAN DINAS'!$U:$U,$K$3,'KENDARAAN DINAS'!$T:$T,A14) -> 0 | M13: =SUMIFS('KENDARAAN DINAS'!$O:$O,'KENDARAAN DINAS'!$U:$U,$M$3,'KENDARAAN DINAS'!$T:$T,A13) -> 0 | N13: =SUMIFS('KENDARAAN DINAS'!$P:$P,'KENDARAAN DINAS'!$U:$U,$M$3,'KENDARAAN DINAS'!$T:$T,A13) -> 0 | O13: =C13+E13+G13+I13+K13+M13 -> 15 | P13: =D13+F13+H13+J13+L13+N13 -> 686217.18
A14: 11 | B14: DINAS PEMBERDAYAAN PEREMPUAN, PERLINDUNGAN ANAK, PENGENDALIAN PENDUDUK DAN KELUARGA BERENCANA | C14: =SUMIFS('KENDARAAN DINAS'!$O:$O,'KENDARAAN DINAS'!$U:$U,'REKAP KENDARAAN DINAS'!$C$3,'KENDARAAN DINAS'!$T:$T,'REKAP KENDARAAN DINAS'!A14) -> 24 | D14: =SUMIFS('KENDARAAN DINAS'!$P:$P,'KENDARAAN DINAS'!$U:$U,'REKAP KENDARAAN DINAS'!$C$3,'KENDARAAN DINAS'!$T:$T,A14) -> 469707.33 | E14: =SUMIFS('KENDARAAN DINAS'!$O:$O,'KENDARAAN DINAS'!$U:$U,$E$3,'KENDARAAN DINAS'!$T:$T,A14) -> 2 | F14: =SUMIFS('KENDARAAN DINAS'!$P:$P,'KENDARAAN DINAS'!$U:$U,$E$3,'KENDARAAN DINAS'!$T:$T,A14) -> 907095 | G14: =SUMIFS('KENDARAAN DINAS'!$O:$O,'KENDARAAN DINAS'!$U:$U,$G$3,'KENDARAAN DINAS'!$T:$T,A14) -> 0 | H14: =SUMIFS('KENDARAAN DINAS'!$P:$P,'KENDARAAN DINAS'!$U:$U,$G$3,'KENDARAAN DINAS'!$T:$T,A14) -> 0 | I14: =SUMIFS('KENDARAAN DINAS'!$O:$O,'KENDARAAN DINAS'!$U:$U,$I$3,'KENDARAAN DINAS'!$T:$T,A14) -> 0 | J14: =SUMIFS('KENDARAAN DINAS'!$P:$P,'KENDARAAN DINAS'!$U:$U,$I$3,'KENDARAAN DINAS'!$T:$T,A14) -> 0 | K14: =SUMIFS('KENDARAAN DINAS'!$O:$O,'KENDARAAN DINAS'!$U:$U,$K$3,'KENDARAAN DINAS'!$T:$T,A14) -> 0 | L14: =SUMIFS('KENDARAAN DINAS'!$P:$P,'KENDARAAN DINAS'!$U:$U,$K$3,'KENDARAAN DINAS'!$T:$T,A15) -> 0 | M14: =SUMIFS('KENDARAAN DINAS'!$O:$O,'KENDARAAN DINAS'!$U:$U,$M$3,'KENDARAAN DINAS'!$T:$T,A14) -> 0 | N14: =SUMIFS('KENDARAAN DINAS'!$P:$P,'KENDARAAN DINAS'!$U:$U,$M$3,'KENDARAAN DINAS'!$T:$T,A14) -> 0 | O14: =C14+E14+G14+I14+K14+M14 -> 26 | P14: =D14+F14+H14+J14+L14+N14 -> 1376802.3
A15: 12 | B15: DINAS KETAHANAN PANGAN DAN PERTANIAN | C15: =SUMIFS('KENDARAAN DINAS'!$O:$O,'KENDARAAN DINAS'!$U:$U,'REKAP KENDARAAN DINAS'!$C$3,'KENDARAAN DINAS'!$T:$T,'REKAP KENDARAAN DINAS'!A15) -> 78 | D15: =SUMIFS('KENDARAAN DINAS'!$P:$P,'KENDARAAN DINAS'!$U:$U,'REKAP KENDARAAN DINAS'!$C$3,'KENDARAAN DINAS'!$T:$T,A15) -> 1174700.5 | E15: =SUMIFS('KENDARAAN DINAS'!$O:$O,'KENDARAAN DINAS'!$U:$U,$E$3,'KENDARAAN DINAS'!$T:$T,A15) -> 5 | F15: =SUMIFS('KENDARAAN DINAS'!$P:$P,'KENDARAAN DINAS'!$U:$U,$E$3,'KENDARAAN DINAS'!$T:$T,A15) -> 1154160 | G15: =SUMIFS('KENDARAAN DINAS'!$O:$O,'KENDARAAN DINAS'!$U:$U,$G$3,'KENDARAAN DINAS'!$T:$T,A15) -> 0 | H15: =SUMIFS('KENDARAAN DINAS'!$P:$P,'KENDARAAN DINAS'!$U:$U,$G$3,'KENDARAAN DINAS'!$T:$T,A15) -> 0 | I15: =SUMIFS('KENDARAAN DINAS'!$O:$O,'KENDARAAN DINAS'!$U:$U,$I$3,'KENDARAAN DINAS'!$T:$T,A15) -> 0 | J15: =SUMIFS('KENDARAAN DINAS'!$P:$P,'KENDARAAN DINAS'!$U:$U,$I$3,'KENDARAAN DINAS'!$T:$T,A15) -> 0 | K15: =SUMIFS('KENDARAAN DINAS'!$O:$O,'KENDARAAN DINAS'!$U:$U,$K$3,'KENDARAAN DINAS'!$T:$T,A15) -> 0 | L15: =SUMIFS('KENDARAAN DINAS'!$P:$P,'KENDARAAN DINAS'!$U:$U,$K$3,'KENDARAAN DINAS'!$T:$T,A16) -> 0 | M15: =SUMIFS('KENDARAAN DINAS'!$O:$O,'KENDARAAN DINAS'!$U:$U,$M$3,'KENDARAAN DINAS'!$T:$T,A15) -> 0 | N15: =SUMIFS('KENDARAAN DINAS'!$P:$P,'KENDARAAN DINAS'!$U:$U,$M$3,'KENDARAAN DINAS'!$T:$T,A15) -> 0 | O15: =C15+E15+G15+I15+K15+M15 -> 83 | P15: =D15+F15+H15+J15+L15+N15 -> 2328860.5
... A35: 32 | B35: KECAMATAN DANAU SEMBULUH | C35: =SUMIFS('KENDARAAN DINAS'!$O:$O,'KENDARAAN DINAS'!$U:$U,'REKAP KENDARAAN DINAS'!$C$3,'KENDARAAN DINAS'!$T:$T,'REKAP KENDARAAN DINAS'!A35) -> 6 | D35: =SUMIFS('KENDARAAN DINAS'!$P:$P,'KENDARAAN DINAS'!$U:$U,'REKAP KENDARAAN DINAS'!$C$3,'KENDARAAN DINAS'!$T:$T,A35) -> 94430.267 | E35: =SUMIFS('KENDARAAN DINAS'!$O:$O,'KENDARAAN DINAS'!$U:$U,$E$3,'KENDARAAN DINAS'!$T:$T,A35) -> 1 | F35: =SUMIFS('KENDARAAN DINAS'!$P:$P,'KENDARAAN DINAS'!$U:$U,$E$3,'KENDARAAN DINAS'!$T:$T,A35) -> 470900 | G35: =SUMIFS('KENDARAAN DINAS'!$O:$O,'KENDARAAN DINAS'!$U:$U,$G$3,'KENDARAAN DINAS'!$T:$T,A35) -> 0 | H35: =SUMIFS('KENDARAAN DINAS'!$P:$P,'KENDARAAN DINAS'!$U:$U,$G$3,'KENDARAAN DINAS'!$T:$T,A35) -> 0 | I35: =SUMIFS('KENDARAAN DINAS'!$O:$O,'KENDARAAN DINAS'!$U:$U,$I$3,'KENDARAAN DINAS'!$T:$T,A35) -> 0 | J35: =SUMIFS('KENDARAAN DINAS'!$P:$P,'KENDARAAN DINAS'!$U:$U,$I$3,'KENDARAAN DINAS'!$T:$T,A35) -> 0 | K35: =SUMIFS('KENDARAAN DINAS'!$O:$O,'KENDARAAN DINAS'!$U:$U,$K$3,'KENDARAAN DINAS'!$T:$T,A35) -> 0 | L35: =SUMIFS('KENDARAAN DINAS'!$P:$P,'KENDARAAN DINAS'!$U:$U,$K$3,'KENDARAAN DINAS'!$T:$T,A36) -> 0 | M35: =SUMIFS('KENDARAAN DINAS'!$O:$O,'KENDARAAN DINAS'!$U:$U,$M$3,'KENDARAAN DINAS'!$T:$T,A35) -> 0 | N35: =SUMIFS('KENDARAAN DINAS'!$P:$P,'KENDARAAN DINAS'!$U:$U,$M$3,'KENDARAAN DINAS'!$T:$T,A35) -> 0 | O35: =C35+E35+G35+I35+K35+M35 -> 7 | P35: =D35+F35+H35+J35+L35+N35 -> 565330.27
A36: 33 | B36: KECAMATAN HANAU | C36: =SUMIFS('KENDARAAN DINAS'!$O:$O,'KENDARAAN DINAS'!$U:$U,'REKAP KENDARAAN DINAS'!$C$3,'KENDARAAN DINAS'!$T:$T,'REKAP KENDARAAN DINAS'!A36) -> 9 | D36: =SUMIFS('KENDARAAN DINAS'!$P:$P,'KENDARAAN DINAS'!$U:$U,'REKAP KENDARAAN DINAS'!$C$3,'KENDARAAN DINAS'!$T:$T,A36) -> 160667.13 | E36: =SUMIFS('KENDARAAN DINAS'!$O:$O,'KENDARAAN DINAS'!$U:$U,$E$3,'KENDARAAN DINAS'!$T:$T,A36) -> 1 | F36: =SUMIFS('KENDARAAN DINAS'!$P:$P,'KENDARAAN DINAS'!$U:$U,$E$3,'KENDARAAN DINAS'!$T:$T,A36) -> 477500 | G36: =SUMIFS('KENDARAAN DINAS'!$O:$O,'KENDARAAN DINAS'!$U:$U,$G$3,'KENDARAAN DINAS'!$T:$T,A36) -> 0 | H36: - | I36: =SUMIFS('KENDARAAN DINAS'!$O:$O,'KENDARAAN DINAS'!$U:$U,$I$3,'KENDARAAN DINAS'!$T:$T,A36) -> 0 | J36: =SUMIFS('KENDARAAN DINAS'!$P:$P,'KENDARAAN DINAS'!$U:$U,$I$3,'KENDARAAN DINAS'!$T:$T,A36) -> 0 | K36: =SUMIFS('KENDARAAN DINAS'!$O:$O,'KENDARAAN DINAS'!$U:$U,$K$3,'KENDARAAN DINAS'!$T:$T,A36) -> 0 | L36: =SUMIFS('KENDARAAN DINAS'!$P:$P,'KENDARAAN DINAS'!$U:$U,$K$3,'KENDARAAN DINAS'!$T:$T,A37) -> 0 | M36: =SUMIFS('KENDARAAN DINAS'!$O:$O,'KENDARAAN DINAS'!$U:$U,$M$3,'KENDARAAN DINAS'!$T:$T,A36) -> 0 | N36: =SUMIFS('KENDARAAN DINAS'!$P:$P,'KENDARAAN DINAS'!$U:$U,$M$3,'KENDARAAN DINAS'!$T:$T,A36) -> 0 | O36: =C36+E36+G36+I36+K36+M36 -> 10 | P36: =D36+F36+H36+J36+L36+N36 -> #VALUE!
A37: 34 | B37: KECAMATAN SERUYAN HILIR | C37: =SUMIFS('KENDARAAN DINAS'!$O:$O,'KENDARAAN DINAS'!$U:$U,'REKAP KENDARAAN DINAS'!$C$3,'KENDARAAN DINAS'!$T:$T,'REKAP KENDARAAN DINAS'!A37) -> 23 | D37: =SUMIFS('KENDARAAN DINAS'!$P:$P,'KENDARAAN DINAS'!$U:$U,'REKAP KENDARAAN DINAS'!$C$3,'KENDARAAN DINAS'!$T:$T,A37) -> 521298.82 | E37: =SUMIFS('KENDARAAN DINAS'!$O:$O,'KENDARAAN DINAS'!$U:$U,$E$3,'KENDARAAN DINAS'!$T:$T,A37) -> 3 | F37: =SUMIFS('KENDARAAN DINAS'!$P:$P,'KENDARAAN DINAS'!$U:$U,$E$3,'KENDARAAN DINAS'!$T:$T,A37) -> 888600 | G37: =SUMIFS('KENDARAAN DINAS'!$O:$O,'KENDARAAN DINAS'!$U:$U,$G$3,'KENDARAAN DINAS'!$T:$T,A37) -> 0 | H37: =SUMIFS('KENDARAAN DINAS'!$P:$P,'KENDARAAN DINAS'!$U:$U,$G$3,'KENDARAAN DINAS'!$T:$T,A37) -> 0 | I37: =SUMIFS('KENDARAAN DINAS'!$O:$O,'KENDARAAN DINAS'!$U:$U,$I$3,'KENDARAAN DINAS'!$T:$T,A37) -> 0 | J37: =SUMIFS('KENDARAAN DINAS'!$P:$P,'KENDARAAN DINAS'!$U:$U,$I$3,'KENDARAAN DINAS'!$T:$T,A37) -> 0 | K37: =SUMIFS('KENDARAAN DINAS'!$O:$O,'KENDARAAN DINAS'!$U:$U,$K$3,'KENDARAAN DINAS'!$T:$T,A37) -> 0 | L37: =SUMIFS('KENDARAAN DINAS'!$P:$P,'KENDARAAN DINAS'!$U:$U,$K$3,'KENDARAAN DINAS'!$T:$T,A38) -> 0 | M37: =SUMIFS('KENDARAAN DINAS'!$O:$O,'KENDARAAN DINAS'!$U:$U,$M$3,'KENDARAAN DINAS'!$T:$T,A37) -> 0 | N37: =SUMIFS('KENDARAAN DINAS'!$P:$P,'KENDARAAN DINAS'!$U:$U,$M$3,'KENDARAAN DINAS'!$T:$T,A37) -> 0 | O37: =C37+E37+G37+I37+K37+M37 -> 26 | P37: =D37+F37+H37+J37+L37+N37 -> 1409898.8
A38: 35 | B38: KECAMATAN SERUYAN HULU | C38: =SUMIFS('KENDARAAN DINAS'!$O:$O,'KENDARAAN DINAS'!$U:$U,'REKAP KENDARAAN DINAS'!$C$3,'KENDARAAN DINAS'!$T:$T,'REKAP KENDARAAN DINAS'!A38) -> 8 | D38: =SUMIFS('KENDARAAN DINAS'!$P:$P,'KENDARAAN DINAS'!$U:$U,'REKAP KENDARAAN DINAS'!$C$3,'KENDARAAN DINAS'!$T:$T,A38) -> 151584.13 | E38: =SUMIFS('KENDARAAN DINAS'!$O:$O,'KENDARAAN DINAS'!$U:$U,$E$3,'KENDARAAN DINAS'!$T:$T,A38) -> 1 | F38: =SUMIFS('KENDARAAN DINAS'!$P:$P,'KENDARAAN DINAS'!$U:$U,$E$3,'KENDARAAN DINAS'!$T:$T,A38) -> 425500 | G38: =SUMIFS('KENDARAAN DINAS'!$O:$O,'KENDARAAN DINAS'!$U:$U,$G$3,'KENDARAAN DINAS'!$T:$T,A38) -> 0 | H38: =SUMIFS('KENDARAAN DINAS'!$P:$P,'KENDARAAN DINAS'!$U:$U,$G$3,'KENDARAAN DINAS'!$T:$T,A38) -> 0 | I38: =SUMIFS('KENDARAAN DINAS'!$O:$O,'KENDARAAN DINAS'!$U:$U,$I$3,'KENDARAAN DINAS'!$T:$T,A38) -> 1 | J38: =SUMIFS('KENDARAAN DINAS'!$P:$P,'KENDARAAN DINAS'!$U:$U,$I$3,'KENDARAAN DINAS'!$T:$T,A38) -> 310000 | K38: =SUMIFS('KENDARAAN DINAS'!$O:$O,'KENDARAAN DINAS'!$U:$U,$K$3,'KENDARAAN DINAS'!$T:$T,A38) -> 0 | L38: =SUMIFS('KENDARAAN DINAS'!$P:$P,'KENDARAAN DINAS'!$U:$U,$K$3,'KENDARAAN DINAS'!$T:$T,A39) -> 0 | M38: =SUMIFS('KENDARAAN DINAS'!$O:$O,'KENDARAAN DINAS'!$U:$U,$M$3,'KENDARAAN DINAS'!$T:$T,A38) -> 0 | N38: =SUMIFS('KENDARAAN DINAS'!$P:$P,'KENDARAAN DINAS'!$U:$U,$M$3,'KENDARAAN DINAS'!$T:$T,A38) -> 0 | O38: =C38+E38+G38+I38+K38+M38 -> 10 | P38: =D38+F38+H38+J38+L38+N38 -> 887084.13
A39: 36 | B39: KECAMATAN BATU AMPAR | C39: =SUMIFS('KENDARAAN DINAS'!$O:$O,'KENDARAAN DINAS'!$U:$U,'REKAP KENDARAAN DINAS'!$C$3,'KENDARAAN DINAS'!$T:$T,'REKAP KENDARAAN DINAS'!A39) -> 6 | D39: =SUMIFS('KENDARAAN DINAS'!$P:$P,'KENDARAAN DINAS'!$U:$U,'REKAP KENDARAAN DINAS'!$C$3,'KENDARAAN DINAS'!$T:$T,A39) -> 119575.76 | E39: =SUMIFS('KENDARAAN DINAS'!$O:$O,'KENDARAAN DINAS'!$U:$U,$E$3,'KENDARAAN DINAS'!$T:$T,A39) -> 2 | F39: =SUMIFS('KENDARAAN DINAS'!$P:$P,'KENDARAAN DINAS'!$U:$U,$E$3,'KENDARAAN DINAS'!$T:$T,A39) -> 870150 | G39: =SUMIFS('KENDARAAN DINAS'!$O:$O,'KENDARAAN DINAS'!$U:$U,$G$3,'KENDARAAN DINAS'!$T:$T,A39) -> 0 | H39: =SUMIFS('KENDARAAN DINAS'!$P:$P,'KENDARAAN DINAS'!$U:$U,$G$3,'KENDARAAN DINAS'!$T:$T,A39) -> 0 | I39: =SUMIFS('KENDARAAN DINAS'!$O:$O,'KENDARAAN DINAS'!$U:$U,$I$3,'KENDARAAN DINAS'!$T:$T,A39) -> 0 | J39: =SUMIFS('KENDARAAN DINAS'!$P:$P,'KENDARAAN DINAS'!$U:$U,$I$3,'KENDARAAN DINAS'!$T:$T,A39) -> 0 | K39: =SUMIFS('KENDARAAN DINAS'!$O:$O,'KENDARAAN DINAS'!$U:$U,$K$3,'KENDARAAN DINAS'!$T:$T,A39) -> 0 | L39: =SUMIFS('KENDARAAN DINAS'!$P:$P,'KENDARAAN DINAS'!$U:$U,$K$3,'KENDARAAN DINAS'!$T:$T,A40) -> 0 | M39: =SUMIFS('KENDARAAN DINAS'!$O:$O,'KENDARAAN DINAS'!$U:$U,$M$3,'KENDARAAN DINAS'!$T:$T,A39) -> 0 | N39: =SUMIFS('KENDARAAN DINAS'!$P:$P,'KENDARAAN DINAS'!$U:$U,$M$3,'KENDARAAN DINAS'!$T:$T,A39) -> 0 | O39: =C39+E39+G39+I39+K39+M39 -> 8 | P39: =D39+F39+H39+J39+L39+N39 -> 989725.76
A40: 37 | B40: KECAMATAN SERUYAN RAYA | C40: =SUMIFS('KENDARAAN DINAS'!$O:$O,'KENDARAAN DINAS'!$U:$U,'REKAP KENDARAAN DINAS'!$C$3,'KENDARAAN DINAS'!$T:$T,'REKAP KENDARAAN DINAS'!A40) -> 4 | D40: =SUMIFS('KENDARAAN DINAS'!$P:$P,'KENDARAAN DINAS'!$U:$U,'REKAP KENDARAAN DINAS'!$C$3,'KENDARAAN DINAS'!$T:$T,A40) -> 78577.55 | E40: =SUMIFS('KENDARAAN DINAS'!$O:$O,'KENDARAAN DINAS'!$U:$U,$E$3,'KENDARAAN DINAS'!$T:$T,A40) -> 0 | F40: =SUMIFS('KENDARAAN DINAS'!$P:$P,'KENDARAAN DINAS'!$U:$U,$E$3,'KENDARAAN DINAS'!$T:$T,A40) -> 0 | G40: =SUMIFS('KENDARAAN DINAS'!$O:$O,'KENDARAAN DINAS'!$U:$U,$G$3,'KENDARAAN DINAS'!$T:$T,A40) -> 0 | H40: =SUMIFS('KENDARAAN DINAS'!$P:$P,'KENDARAAN DINAS'!$U:$U,$G$3,'KENDARAAN DINAS'!$T:$T,A40) -> 0 | I40: =SUMIFS('KENDARAAN DINAS'!$O:$O,'KENDARAAN DINAS'!$U:$U,$I$3,'KENDARAAN DINAS'!$T:$T,A40) -> 0 | J40: =SUMIFS('KENDARAAN DINAS'!$P:$P,'KENDARAAN DINAS'!$U:$U,$I$3,'KENDARAAN DINAS'!$T:$T,A40) -> 0 | K40: =SUMIFS('KENDARAAN DINAS'!$O:$O,'KENDARAAN DINAS'!$U:$U,$K$3,'KENDARAAN DINAS'!$T:$T,A40) -> 0 | L40: =SUMIFS('KENDARAAN DINAS'!$P:$P,'KENDARAAN DINAS'!$U:$U,$K$3,'KENDARAAN DINAS'!$T:$T,A41) -> 0 | M40: =SUMIFS('KENDARAAN DINAS'!$O:$O,'KENDARAAN DINAS'!$U:$U,$M$3,'KENDARAAN DINAS'!$T:$T,A40) -> 0 | N40: =SUMIFS('KENDARAAN DINAS'!$P:$P,'KENDARAAN DINAS'!$U:$U,$M$3,'KENDARAAN DINAS'!$T:$T,A40) -> 0 | O40: =C40+E40+G40+I40+K40+M40 -> 4 | P40: =D40+F40+H40+J40+L40+N40 -> 78577.55
A41: 38 | B41: KECAMATAN DANAU SELULUK | C41: =SUMIFS('KENDARAAN DINAS'!$O:$O,'KENDARAAN DINAS'!$U:$U,'REKAP KENDARAAN DINAS'!$C$3,'KENDARAAN DINAS'!$T:$T,'REKAP KENDARAAN DINAS'!A41) -> 4 | D41: =SUMIFS('KENDARAAN DINAS'!$P:$P,'KENDARAAN DINAS'!$U:$U,'REKAP KENDARAAN DINAS'!$C$3,'KENDARAAN DINAS'!$T:$T,A41) -> 68091.683 | E41: =SUMIFS('KENDARAAN DINAS'!$O:$O,'KENDARAAN DINAS'!$U:$U,$E$3,'KENDARAAN DINAS'!$T:$T,A41) -> 1 | F41: =SUMIFS('KENDARAAN DINAS'!$P:$P,'KENDARAAN DINAS'!$U:$U,$E$3,'KENDARAAN DINAS'!$T:$T,A41) -> 477500 | G41: =SUMIFS('KENDARAAN DINAS'!$O:$O,'KENDARAAN DINAS'!$U:$U,$G$3,'KENDARAAN DINAS'!$T:$T,A41) -> 0 | H41: =SUMIFS('KENDARAAN DINAS'!$P:$P,'KENDARAAN DINAS'!$U:$U,$G$3,'KENDARAAN DINAS'!$T:$T,A41) -> 0 | I41: =SUMIFS('KENDARAAN DINAS'!$O:$O,'KENDARAAN DINAS'!$U:$U,$I$3,'KENDARAAN DINAS'!$T:$T,A41) -> 0 | J41: =SUMIFS('KENDARAAN DINAS'!$P:$P,'KENDARAAN DINAS'!$U:$U,$I$3,'KENDARAAN DINAS'!$T:$T,A41) -> 0 | K41: =SUMIFS('KENDARAAN DINAS'!$O:$O,'KENDARAAN DINAS'!$U:$U,$K$3,'KENDARAAN DINAS'!$T:$T,A41) -> 0 | L41: =SUMIFS('KENDARAAN DINAS'!$P:$P,'KENDARAAN DINAS'!$U:$U,$K$3,'KENDARAAN DINAS'!$T:$T,A42) -> 0 | M41: =SUMIFS('KENDARAAN DINAS'!$O:$O,'KENDARAAN DINAS'!$U:$U,$M$3,'KENDARAAN DINAS'!$T:$T,A41) -> 0 | N41: =SUMIFS('KENDARAAN DINAS'!$P:$P,'KENDARAAN DINAS'!$U:$U,$M$3,'KENDARAAN DINAS'!$T:$T,A41) -> 0 | O41: =C41+E41+G41+I41+K41+M41 -> 5 | P41: =D41+F41+H41+J41+L41+N41 -> 545591.68
A42: 39 | B42: KECAMATAN SERUYAN HILIR TIMUR | C42: =SUMIFS('KENDARAAN DINAS'!$O:$O,'KENDARAAN DINAS'!$U:$U,'REKAP KENDARAAN DINAS'!$C$3,'KENDARAAN DINAS'!$T:$T,'REKAP KENDARAAN DINAS'!A42) -> 3 | D42: =SUMIFS('KENDARAAN DINAS'!$P:$P,'KENDARAAN DINAS'!$U:$U,'REKAP KENDARAAN DINAS'!$C$3,'KENDARAAN DINAS'!$T:$T,A42) -> 45875.583 | E42: =SUMIFS('KENDARAAN DINAS'!$O:$O,'KENDARAAN DINAS'!$U:$U,$E$3,'KENDARAAN DINAS'!$T:$T,A42) -> 1 | F42: =SUMIFS('KENDARAAN DINAS'!$P:$P,'KENDARAAN DINAS'!$U:$U,$E$3,'KENDARAAN DINAS'!$T:$T,A42) -> 477500 | G42: =SUMIFS('KENDARAAN DINAS'!$O:$O,'KENDARAAN DINAS'!$U:$U,$G$3,'KENDARAAN DINAS'!$T:$T,A42) -> 0 | H42: =SUMIFS('KENDARAAN DINAS'!$P:$P,'KENDARAAN DINAS'!$U:$U,$G$3,'KENDARAAN DINAS'!$T:$T,A42) -> 0 | I42: =SUMIFS('KENDARAAN DINAS'!$O:$O,'KENDARAAN DINAS'!$U:$U,$I$3,'KENDARAAN DINAS'!$T:$T,A42) -> 0 | J42: =SUMIFS('KENDARAAN DINAS'!$P:$P,'KENDARAAN DINAS'!$U:$U,$I$3,'KENDARAAN DINAS'!$T:$T,A42) -> 0 | K42: =SUMIFS('KENDARAAN DINAS'!$O:$O,'KENDARAAN DINAS'!$U:$U,$K$3,'KENDARAAN DINAS'!$T:$T,A42) -> 0 | L42: =SUMIFS('KENDARAAN DINAS'!$P:$P,'KENDARAAN DINAS'!$U:$U,$K$3,'KENDARAAN DINAS'!$T:$T,A43) -> 0 | M42: =SUMIFS('KENDARAAN DINAS'!$O:$O,'KENDARAAN DINAS'!$U:$U,$M$3,'KENDARAAN DINAS'!$T:$T,A42) -> 0 | N42: =SUMIFS('KENDARAAN DINAS'!$P:$P,'KENDARAAN DINAS'!$U:$U,$M$3,'KENDARAAN DINAS'!$T:$T,A42) -> 0 | O42: =C42+E42+G42+I42+K42+M42 -> 4 | P42: =D42+F42+H42+J42+L42+N42 -> 523375.58
A43: 40 | B43: KECAMATAN SULING TAMBUN | C43: =SUMIFS('KENDARAAN DINAS'!$O:$O,'KENDARAAN DINAS'!$U:$U,'REKAP KENDARAAN DINAS'!$C$3,'KENDARAAN DINAS'!$T:$T,'REKAP KENDARAAN DINAS'!A43) -> 6 | D43: =SUMIFS('KENDARAAN DINAS'!$P:$P,'KENDARAAN DINAS'!$U:$U,'REKAP KENDARAAN DINAS'!$C$3,'KENDARAAN DINAS'!$T:$T,A43) -> 118176.53 | E43: =SUMIFS('KENDARAAN DINAS'!$O:$O,'KENDARAAN DINAS'!$U:$U,$E$3,'KENDARAAN DINAS'!$T:$T,A43) -> 2 | F43: =SUMIFS('KENDARAAN DINAS'!$P:$P,'KENDARAAN DINAS'!$U:$U,$E$3,'KENDARAAN DINAS'!$T:$T,A43) -> 625000 | G43: =SUMIFS('KENDARAAN DINAS'!$O:$O,'KENDARAAN DINAS'!$U:$U,$G$3,'KENDARAAN DINAS'!$T:$T,A43) -> 0 | H43: =SUMIFS('KENDARAAN DINAS'!$P:$P,'KENDARAAN DINAS'!$U:$U,$G$3,'KENDARAAN DINAS'!$T:$T,A43) -> 0 | I43: =SUMIFS('KENDARAAN DINAS'!$O:$O,'KENDARAAN DINAS'!$U:$U,$I$3,'KENDARAAN DINAS'!$T:$T,A43) -> 1 | J43: =SUMIFS('KENDARAAN DINAS'!$P:$P,'KENDARAAN DINAS'!$U:$U,$I$3,'KENDARAAN DINAS'!$T:$T,A43) -> 310000 | K43: =SUMIFS('KENDARAAN DINAS'!$O:$O,'KENDARAAN DINAS'!$U:$U,$K$3,'KENDARAAN DINAS'!$T:$T,A43) -> 0 | L43: =SUMIFS('KENDARAAN DINAS'!$P:$P,'KENDARAAN DINAS'!$U:$U,$K$3,'KENDARAAN DINAS'!$T:$T,A44) -> 0 | M43: =SUMIFS('KENDARAAN DINAS'!$O:$O,'KENDARAAN DINAS'!$U:$U,$M$3,'KENDARAAN DINAS'!$T:$T,A43) -> 0 | N43: =SUMIFS('KENDARAAN DINAS'!$P:$P,'KENDARAAN DINAS'!$U:$U,$M$3,'KENDARAAN DINAS'!$T:$T,A43) -> 0 | O43: =C43+E43+G43+I43+K43+M43 -> 9 | P43: =D43+F43+H43+J43+L43+N43 -> 1053176.5
A44: 41 | B44: BADAN PENANGGULANGAN BENCANA DAERAH | C44: =SUMIFS('KENDARAAN DINAS'!$O:$O,'KENDARAAN DINAS'!$U:$U,'REKAP KENDARAAN DINAS'!$C$3,'KENDARAAN DINAS'!$T:$T,'REKAP KENDARAAN DINAS'!A44) -> 186 | D44: =SUMIFS('KENDARAAN DINAS'!$P:$P,'KENDARAAN DINAS'!$U:$U,'REKAP KENDARAAN DINAS'!$C$3,'KENDARAAN DINAS'!$T:$T,A44) -> 6335314 | E44: =SUMIFS('KENDARAAN DINAS'!$O:$O,'KENDARAAN DINAS'!$U:$U,$E$3,'KENDARAAN DINAS'!$T:$T,A44) -> 20 | F44: =SUMIFS('KENDARAAN DINAS'!$P:$P,'KENDARAAN DINAS'!$U:$U,$E$3,'KENDARAAN DINAS'!$T:$T,A44) -> 14193619 | G44: =SUMIFS('KENDARAAN DINAS'!$O:$O,'KENDARAAN DINAS'!$U:$U,$G$3,'KENDARAAN DINAS'!$T:$T,A44) -> 0 | H44: =SUMIFS('KENDARAAN DINAS'!$P:$P,'KENDARAAN DINAS'!$U:$U,$G$3,'KENDARAAN DINAS'!$T:$T,A44) -> 0 | I44: =SUMIFS('KENDARAAN DINAS'!$O:$O,'KENDARAAN DINAS'!$U:$U,$I$3,'KENDARAAN DINAS'!$T:$T,A44) -> 28 | J44: =SUMIFS('KENDARAAN DINAS'!$P:$P,'KENDARAAN DINAS'!$U:$U,$I$3,'KENDARAAN DINAS'!$T:$T,A44) -> 31804526 | K44: =SUMIFS('KENDARAAN DINAS'!$O:$O,'KENDARAAN DINAS'!$U:$U,$K$3,'KENDARAAN DINAS'!$T:$T,A44) -> 0 | L44: =SUMIFS('KENDARAAN DINAS'!$P:$P,'KENDARAAN DINAS'!$U:$U,$K$3,'KENDARAAN DINAS'!$T:$T,A45) -> 0 | M44: =SUMIFS('KENDARAAN DINAS'!$O:$O,'KENDARAAN DINAS'!$U:$U,$M$3,'KENDARAAN DINAS'!$T:$T,A44) -> 0 | N44: =SUMIFS('KENDARAAN DINAS'!$P:$P,'KENDARAAN DINAS'!$U:$U,$M$3,'KENDARAAN DINAS'!$T:$T,A44) -> 0 | O44: =C44+E44+G44+I44+K44+M44 -> 234 | P44: =D44+F44+H44+J44+L44+N44 -> 52333459
A45: 42 | B45: DAMKAR | C45: =SUMIFS('KENDARAAN DINAS'!$O:$O,'KENDARAAN DINAS'!$U:$U,'REKAP KENDARAAN DINAS'!$C$3,'KENDARAAN DINAS'!$T:$T,'REKAP KENDARAAN DINAS'!A45) -> 6 | D45: =SUMIFS('KENDARAAN DINAS'!$P:$P,'KENDARAAN DINAS'!$U:$U,'REKAP KENDARAAN DINAS'!$C$3,'KENDARAAN DINAS'!$T:$T,A45) -> 110786 | E45: =SUMIFS('KENDARAAN DINAS'!$O:$O,'KENDARAAN DINAS'!$U:$U,$E$3,'KENDARAAN DINAS'!$T:$T,A45) -> 2 | F45: =SUMIFS('KENDARAAN DINAS'!$P:$P,'KENDARAAN DINAS'!$U:$U,$E$3,'KENDARAAN DINAS'!$T:$T,A45) -> 634150 | G45: =SUMIFS('KENDARAAN DINAS'!$O:$O,'KENDARAAN DINAS'!$U:$U,$G$3,'KENDARAAN DINAS'!$T:$T,A45) -> 0 | H45: =SUMIFS('KENDARAAN DINAS'!$P:$P,'KENDARAAN DINAS'!$U:$U,$G$3,'KENDARAAN DINAS'!$T:$T,A45) -> 0 | I45: =SUMIFS('KENDARAAN DINAS'!$O:$O,'KENDARAAN DINAS'!$U:$U,$I$3,'KENDARAAN DINAS'!$T:$T,A45) -> 6 | J45: =SUMIFS('KENDARAAN DINAS'!$P:$P,'KENDARAAN DINAS'!$U:$U,$I$3,'KENDARAAN DINAS'!$T:$T,A45) -> 3.7757764e+09 | K45: =SUMIFS('KENDARAAN DINAS'!$O:$O,'KENDARAAN DINAS'!$U:$U,$K$3,'KENDARAAN DINAS'!$T:$T,A45) -> 0 | L45: =SUMIFS('KENDARAAN DINAS'!$P:$P,'KENDARAAN DINAS'!$U:$U,$K$3,'KENDARAAN DINAS'!$T:$T,A46) -> 0 | M45: =SUMIFS('KENDARAAN DINAS'!$O:$O,'KENDARAAN DINAS'!$U:$U,$M$3,'KENDARAAN DINAS'!$T:$T,A45) -> 0 | N45: =SUMIFS('KENDARAAN DINAS'!$P:$P,'KENDARAAN DINAS'!$U:$U,$M$3,'KENDARAAN DINAS'!$T:$T,A45) -> 0 | O45: =C45+E45+G45+I45+K45+M45 -> 14 | P45: =D45+F45+H45+J45+L45+N45 -> 3.7765214e+09
A46: 42 | B46: PEMKAB SERUYAN | C46: =SUBTOTAL(9,C4:C45) -> 1252 | D46: =SUBTOTAL(9,D4:D45) -> 27998854 | E46: =SUBTOTAL(9,E4:E45) -> 260 | F46: =SUBTOTAL(9,F4:F44) -> 1.0354481e+08 | G46: =SUBTOTAL(9,G4:G45) -> 1 | H46: =SUBTOTAL(9,H4:H45) -> 1289375 | I46: =SUBTOTAL(9,I4:I45) -> 61 | J46: =SUBTOTAL(9,J4:J45) -> 3.8242519e+09 | K46: =SUBTOTAL(9,K4:K45) -> 0 | L46: =SUBTOTAL(9,L4:L45) -> 0 | M46: =SUBTOTAL(9,M4:M45) -> 0 | N46: =SUBTOTAL(9,N4:N45) -> 0 | ... P46: =SUBTOTAL(9,P4:P45) -> #VALUE!

Sheet KIB A - Tanah
H2: KARTU INVENTARIS BARANG (KIB)
I3: A. TANAH
A5: No. | B5: Jenis barang/ | E5: Luas | F5: Tahun | G5: Letak/
B6: Nama barang | C6: Kode | D6: Register | E6: (M2) | F6: penga- | G6: alamat | H6: Hak | I6: Sertifikat | K6: penggunaan | L6: Asal usul | M6: Harga | N6: Keterangan | O6: SKPD
C7: Barang | F7: daan | I7: Tanggal | J7: Nomor
A9: 1 | B9: Tanah Bangunan Pendidikan Dan Latihan | C9: 01.01.01.04.002 | D9: 000001 | E9: 2000 | F9: 2003 | G9: Desa Ayawan Kecamatan Seruyan Tengah | H9: Hak Pakai | K9: Gedung Sekolah | L9: pembelian | M9: 7150 | N9: Nilai Pasar | O9: sdn 1 ayawan | P9: 1
A10: 2 | B10: Tanah Bangunan Pendidikan Dan Latihan | C10: 01.01.01.04.002 | D10: 000002 | E10: 1386 | F10: 2014 | G10: Desa Ayawan Kecamatan Seruyan Tengah | H10: Hak Pakai | K10: Gedung Sekolah | L10: Hibah | M10: 10000 | N10: Hibah Kotim | O10: sdn 1 ayawan | P10: 1
A11: 3 | B11: Tanah Bangunan Pendidikan Dan Latihan | C11: 01.01.01.04.002 | D11: 000001 | E11: 10554 | F11: 2003 | G11: Desa BIII Sukamandang Kecamatan Seruyan Tengah | H11: Hak Pakai | I11: 44481 | J11: 15.11.02.26.4.00014 | K11: Gedung Sekolah | L11: pembelian | M11: 80850 | N11: Nilai Pasar | O11: sdn 1 batu agung | P11: 1
A12: 4 | B12: Tanah Bangunan Pendidikan Dan Latihan | C12: 01.01.01.04.002 | D12: 000002 | E12: 2500 | F12: 2014 | G12: Desa BIII Sukamandang Kecamatan Seruyan Tengah | H12: Hak Pakai | K12: Gedung Sekolah | L12: Hibah | M12: 36000 | N12: Hibah Kotim | O12: sdn 1 batu agung | P12: 1
A13: 5 | B13: Tanah Bangunan Pendidikan Dan Latihan | C13: 01.01.01.04.002 | D13: 000001 | E13: 2000 | F13: 2003 | G13: Desa Bukit Buluh Kecamatan Seruyan Tengah | H13: Hak Pakai | K13: Gedung Sekolah | L13: pembelian | M13: 7450 | N13: Nilai Pasar | O13: sdn 1 bukit buluh | P13: 1
A14: 6 | B14: Tanah Bangunan Pendidikan Dan Latihan | C14: 01.01.01.04.002 | D14: 000002 | E14: 2000 | F14: 2014 | G14: Desa Bukit Buluh Kecamatan Seruyan Tengah | H14: Hak Pakai | K14: Gedung Sekolah | L14: Hibah | M14: 10000 | N14: Hibah Kotim | O14: sdn 1 bukit buluh | P14: 1
A15: 7 | B15: Tanah Bangunan Pendidikan Dan Latihan | C15: 01.01.01.04.002 | D15: 000001 | E15: 20000 | F15: 2003 | G15: Desa GII Sukamandang Kecamatan Seruyan Tengah | H15: Hak Pakai | K15: Gedung Sekolah | L15: pembelian | M15: 72000 | N15: Nilai Pasar | O15: sdn 1 bumi jaya | P15: 1
A16: 8 | B16: Tanah Bangunan Pendidikan Dan Latihan | C16: 01.01.01.04.002 | D16: 000002 | E16: 2000 | F16: 2014 | G16: Desa GII Sukamandang Kecamatan Seruyan Tengah | H16: Hak Pakai | K16: Gedung Sekolah | L16: Hibah | M16: 10000 | N16: Hibah Kotim | O16: sdn 1 bumi jaya | P16: 1
A17: 9 | B17: Tanah Bangunan Pendidikan Dan Latihan | C17: 01.01.01.04.002 | D17: 000001 | E17: 2700 | F17: 2003 | G17: Desa Durian Tunggal Kecamatan Seruyan Tengah | H17: Hak Pakai | K17: Gedung Sekolah | L17: pembelian | M17: 9923 | N17: Nilai Pasar | O17: sdn 1 durian tunggal | P17: 1
A18: 10 | B18: Tanah Bangunan Pendidikan Dan Latihan | C18: 01.01.01.04.002 | D18: 000002 | E18: 17586 | F18: 2014 | G18: Desa Durian Tunggal Kecamatan Seruyan Tengah | H18: Hak Pakai | K18: Gedung Sekolah | L18: Hibah | M18: 9000 | N18: Hibah Kotim | O18: sdn 1 durian tunggal | P18: 1
A19: 11 | B19: Tanah Bangunan Pendidikan Dan Latihan | C19: 01.01.01.04.002 | D19: 000001 | E19: 10731 | F19: 2003 | G19: Desa Gantung Pengayuh Kecamatan Seruyan Tengah | H19: Hak Pakai | K19: Gedung Sekolah | L19: pembelian | M19: 39168 | N19: Nilai Pasar | O19: sdn 1 gantung pengayuh | P19: 1
A20: 12 | B20: Tanah Bangunan Pendidikan Dan Latihan | C20: 01.01.01.04.002 | D20: 000002 | E20: 2000 | F20: 2014 | G20: Desa Gantung Pengayuh Kecamatan Seruyan Tengah | H20: Hak Pakai | K20: Gedung Sekolah | L20: Hibah | M20: 10000 | N20: Hibah Kotim | O20: sdn 1 gantung pengayuh | P20: 1
A21: 13 | B21: Tanah Bangunan Pendidikan Dan Latihan | C21: 01.01.01.04.002 | D21: 000001 | E21: 1386 | F21: 2014 | G21: Desa Mugi Penyuhu Kecamatan Seruyan Tengah | H21: Hak Pakai | K21: Gedung Sekolah | L21: Hibah | M21: 10000 | N21: Hibah Kotim | O21: sdn 1 mugi penyuhu | P21: 1
A22: 14 | B22: Tanah Bangunan Pendidikan Dan Latihan | C22: 01.01.01.04.002 | D22: 000001 | E22: 2500 | F22: 2014 | G22: Desa DT I Sukamandang Kecamatan Seruyan Tengah | H22: Hak Pakai | K22: Gedung Sekolah | L22: Hibah | M22: 37500 | N22: Hibah Kotim | O22: sdn 1 panca jaya | P22: 1
A23: 15 | B23: Tanah Bangunan Pendidikan Dan Latihan | C23: 01.01.01.04.002 | D23: 000001 | E23: 1400 | F23: 2003 | G23: Desa Pangke Kecamatan Seruyan Tengah | H23: Hak Pakai | K23: Gedung Sekolah | L23: pembelian | M23: 5215 | N23: Nilai Pasar | O23: sdn 1 pangke | P23: 1
A24: 16 | B24: Tanah Bangunan Pendidikan Dan Latihan | C24: 01.01.01.04.002 | D24: 000002 | E24: 600 | F24: 2014 | G24: Desa Pangke Kecamatan Seruyan Tengah | H24: Hak Pakai | K24: Gedung Sekolah | L24: Hibah | M24: 25000 | N24: Hibah Kotim | O24: sdn 1 pangke | P24: 1
A25: 17 | B25: Tanah Bangunan Pendidikan Dan Latihan | C25: 01.01.01.04.002 | D25: 000001 | E25: 613 | F25: 2014 | G25: Desa Panyumpa Kecamatan Seruyan Tengah | H25: Hak Pakai | I25: 44523 | J25: 15.11.02.10.4.00013 | K25: Gedung Sekolah | L25: Hibah | M25: 14000 | N25: Hibah Kotim | O25: sdn 1 panyumpa | P25: 1
A26: 18 | B26: Tanah Bangunan Pendidikan Dan Latihan | C26: 01.01.01.04.002 | D26: 000002 | E26: 5746 | F26: 2003 | G26: Desa Panyumpa Kecamatan Seruyan Tengah | H26: Hak Pakai | I26: 44523 | J26: 15.11.02.10.4.00017 | K26: Gedung Sekolah | L26: pembelian | M26: 9250 | N26: Nilai Pasar | O26: sdn 1 panyumpa | P26: 1
A27: 19 | B27: Tanah Bangunan Rumah Negara Tanpa Golongan | C27: 01.01.01.01.004 | D27: 000001 | E27: 358 | F27: 2024 | G27: Jl. Tajudin Kusuma Rantau Pulut Seruyan Tengah | H27: Hak Pakai | I27: 39237 | J27: 15.11.02.16.2.00001 | K27: Perumahan Guru SDN I Rantau Pulut | L27: Hibah | M27: 17184 | N27: Berdasarkan Keputusan Bupati Seruyan No.100.3.3.2/720/2024 | O27: sdn 1 rantau pulut | P27: 1
A28: 20 | B28: Tanah Bangunan Pendidikan Dan Latihan | C28: 01.01.01.04.002 | D28: 000001 | E28: 107 | F28: 2014 | G28: Jalan Sajudin Kusuma | H28: Hak Pakai | I28: 39237 | J28: 15.11.02.16.2.00003 | K28: Gedung Sekolah | L28: Hibah | M28: 37800 | N28: Hibah Kotim | O28: sdn 1 rantau pulut | P28: 1
A29: 21 | B29: Tanah Bangunan Pendidikan Dan Latihan | C29: 01.01.01.04.002 | D29: 000002 | E29: 3748 | F29: 2008 | G29: Jalan Sajudin Kusuma | H29: Hak Pakai | I29: 39567 | J29: 15.11.02.16.2.00010 | K29: Gedung Sekolah | L29: pembelian | M29: 17053 | N29: Nilai Pasar | O29: sdn 1 rantau pulut | P29: 1
A30: 22 | B30: Tanah Bangunan Pendidikan Dan Latihan | C30: 01.01.01.04.002 | D30: 000001 | E30: 12830 | F30: 2014 | G30: Desa DT II Sukamandang Kecamatan Seruyan Tengah | H30: Hak Pakai | I30: 44434 | J30: 15.11.02.22.4.00034 | K30: Gedung Sekolah | L30: Hibah | M30: 11250 | N30: Hibah Kotim | O30: sdn 1 ringin agung | P30: 1
A31: 23 | B31: Tanah Bangunan Pendidikan Dan Latihan | C31: 01.01.01.04.002 | D31: 000001 | E31: 500000 | F31: 2003 | G31: Desa BI Sukamandang Kecamatan Seruyan Tengah | H31: Hak Pakai | K31: Gedung Sekolah | L31: pembelian | M31: 1837500 | N31: Nilai Pasar | O31: sdn 1 suka maju | P31: 1
A32: 24 | B32: Tanah Bangunan Pendidikan Dan Latihan | C32: 01.01.01.04.002 | D32: 000002 | E32: 40000 | F32: 2014 | G32: Desa BI Sukamandang Kecamatan Seruyan Tengah | H32: Hak Pakai | K32: Gedung Sekolah | L32: Hibah | M32: 45000 | N32: Hibah Kotim | O32: sdn 1 suka maju | P32: 1
A33: 25 | B33: Tanah Bangunan Pendidikan Dan Latihan | C33: 01.01.01.04.002 | D33: 000001 | E33: 12864 | F33: 2014 | G33: Desa B II Sukamandang Kecamatan Seruyan Tengah | H33: Hak Pakai | K33: Gedung Sekolah | L33: Hibah | M33: 25430 | N33: Hibah Kotim | O33: sdn 1 suka makmur | P33: 1
A34: 26 | B34: Tanah Bangunan Pendidikan Dan Latihan | C34: 01.01.01.04.002 | D34: 000002 | E34: 22000 | F34: 2003 | G34: Desa B II Sukamandang Kecamatan Seruyan Tengah | H34: Hak Pakai | K34: Gedung Sekolah | L34: pembelian | M34: 80850 | N34: Nilai Pasar | O34: sdn 1 suka makmur | P34: 1
A35: 27 | B35: Tanah Bangunan Pendidikan Dan Latihan | C35: 01.01.01.04.002 | D35: 000001 | E35: 9912 | F35: 2014 | G35: Desa BIV Sukamandang Kecamatan Seruyan Tengah | H35: Hak Pakai | K35: Gedung Sekolah | L35: Hibah | M35: 25410 | N35: Hibah Kotim | O35: sdn 1 sukajaya | P35: 1
A36: 28 | B36: Tanah Bangunan Pendidikan Dan Latihan | C36: 01.01.01.04.002 | D36: 000001 | E36: 10000 | F36: 2014 | G36: Desa Sukamandang Kecamatan Seruyan Tengah | H36: Hak Pakai | K36: Gedung Sekolah | L36: Hibah | M36: 2000 | N36: Hibah Kotim | O36: sdn 1 sukamandang | P36: 1
A37: 29 | B37: Tanah Bangunan Pendidikan Dan Latihan | C37: 01.01.01.04.002 | D37: 000002 | E37: 3000 | F37: 2003 | G37: Desa Sukamandang Kecamatan Seruyan Tengah | H37: Hak Pakai | K37: Gedung Sekolah | L37: pembelian | M37: 11175 | N37: Nilai Pasar | O37: sdn 1 sukamandang | P37: 1
A38: 30 | B38: Tanah Bangunan Pendidikan Dan Latihan | C38: 01.01.01.04.002 | D38: 000001 | E38: 2000 | F38: 2014 | G38: Desa G1 Sukamandang Kecamatan Seruyan Tengah | H38: Hak Pakai | K38: Gedung Sekolah | L38: Hibah | M38: 10000 | N38: Hibah Kotim | O38: sdn 1 sukorejo | P38: 1
A39: 31 | B39: Tanah Bangunan Pendidikan Dan Latihan | C39: 01.01.01.04.002 | D39: 000002 | E39: 3000 | F39: 2003 | G39: Desa G1 Sukamandang Kecamatan Seruyan Tengah | H39: Hak Pakai | K39: Gedung Sekolah | L39: pembelian | M39: 10800 | N39: Nilai Pasar | O39: sdn 1 sukorejo | P39: 1
A40: 32 | B40: Tanah Bangunan Pendidikan Dan Latihan | C40: 01.01.01.04.002 | D40: 000001 | E40: 8585 | F40: 2014 | G40: Desa Tangga Batu Kecamatan Seruyan Tengah | H40: Hak Pakai | I40: 44483 | J40: 15.11.02.12.4.00009 | K40: Gedung Sekolah | L40: Hibah | M40: 10000 | N40: Hibah Kotim | O40: sdn 1 tangga batu | P40: 1
A41: 33 | B41: Tanah Bangunan Pendidikan Dan Latihan | C41: 01.01.01.04.002 | D41: 000001 | E41: 2000 | F41: 2014 | G41: Desa Teluk Bayur Kecamatan Seruyan Tengah | H41: Hak Pakai | K41: Gedung Sekolah | L41: Hibah | M41: 10000 | N41: Hibah Kotim | O41: sdn 1 teluk bayur | P41: 1
A42: 34 | B42: Tanah Bangunan Pendidikan Dan Latihan | C42: 01.01.01.04.002 | D42: 000002 | E42: 1320 | F42: 2003 | G42: Desa Teluk Bayur Kecamatan Seruyan Tengah | H42: Hak Pakai | K42: Gedung Sekolah | L42: pembelian | M42: 4884 | N42: Nilai Pasar | O42: sdn 1 teluk bayur | P42: 1
A43: 35 | B43: Tanah Bangunan Pendidikan Dan Latihan | C43: 01.01.01.04.002 | D43: 000001 | E43: 17586 | F43: 2014 | G43: Desa Tumbang Bai Kecamatan Seruyan Tengah | H43: Hak Pakai | K43: Gedung Sekolah | L43: Hibah | M43: 15000 | N43: Hibah Kotim | O43: sdn 1 tumbang bai | P43: 1
...

Sheet KIB C - Gedung dan Bangunan
A2: PEMERINTAH KABUPATEN SERUYAN
A3: KARTU INVENTARIS BARANG (KIB C)
A4: GEDUNG DAN BANGUNAN
A8: No. Urut | B8: Jenis Barang/Nama Barang | E8: Kondisi bangunan (B,KB,RB) | H8: Luas Lantai (M2) | I8: Letak/Lokasi Alamat | N8: Nomor | P8: Harga
C9: Kode | D9: Register | F9: Bertingkat | G9: Beton/ | J9: Tanggal | K9: Nomor | L9: Luas | M9: Status Tanah | N9: kode tanah | O9: Asal Usul | Q9: Ket. | R9: SKPD
C10: barang | F10: Tidak | G10: tidak | L10: (M2)
A12: 1 | B12: Bangunan Gedung Pendidikan Permanen | C12: 03.01.01.10.001 | D12: 000001 | E12: Baik | F12: Tidak | G12: Tidak | H12: 90 | I12: Desa Bahaur, Kecamatan Hanau | M12: Tanah Milik Pemda | O12: pembelian | P12: 177585000 | R12: sdn 1 bahaur | S12: 1
A13: 2 | B13: Bangunan Gedung Pendidikan Permanen | C13: 03.01.01.10.001 | D13: 000002 | E13: Baik | F13: Tidak | G13: Tidak | H13: 135 | I13: Desa Bahaur, Kecamatan Hanau | M13: Tanah Milik Pemda | O13: pembelian | P13: 520878000 | R13: sdn 1 bahaur | S13: 1
A14: 3 | B14: Rumah Negara Golongan I Tipe E Permanen | C14: 03.01.02.01.013 | D14: 000001 | E14: Baik | F14: Tidak | G14: Tidak | H14: 56 | I14: Desa Bahaur, Kecamatan Hanau | M14: Tanah Milik Pemda | O14: pembelian | P14: 159724000 | R14: sdn 1 bahaur | S14: 1
A15: 4 | B15: Bangunan Gedung Pendidikan Permanen | C15: 03.01.01.10.001 | D15: 000001 | E15: Baik | F15: Tidak | G15: Tidak | H15: 260 | I15: Desa Derangga, Kecamatan Hanau | M15: Tanah Milik Pemda | O15: Hibah | P15: 92000000 | Q15: HIBAH KOTIM | R15: sdn 1 derangga | S15: 1
A16: 5 | B16: Bangunan Gedung Pendidikan Permanen | C16: 03.01.01.10.001 | D16: 000002 | E16: Baik | F16: Tidak | G16: Tidak | H16: 45 | I16: Desa Derangga, Kecamatan Hanau | M16: Tanah Milik Pemda | O16: pembelian | P16: 85636000 | R16: sdn 1 derangga | S16: 1
A17: 6 | B17: Bangunan Gedung Pendidikan Permanen | C17: 03.01.01.10.001 | D17: 000003 | E17: Baik | F17: Tidak | G17: Tidak | H17: 135 | I17: Desa Derangga, Kecamatan Hanau | M17: Tanah Milik Pemda | O17: pembelian | P17: 472687000 | R17: sdn 1 derangga | S17: 1
A18: 7 | B18: Bangunan Gedung Pendidikan Permanen | C18: 03.01.01.10.001 | D18: 000004 | E18: Baik | F18: Tidak | G18: Tidak | H18: 90 | I18: Desa Derangga, Kecamatan Hanau | M18: Tanah Milik Pemda | O18: pembelian | P18: 116471000 | R18: sdn 1 derangga | S18: 1
A19: 8 | B19: Bangunan Gedung Pendidikan Permanen | C19: 03.01.01.10.001 | D19: 000005 | E19: Baik | F19: Tidak | G19: Tidak | H19: 90 | I19: Desa Derangga, Kecamatan Hanau | M19: Tanah Milik Pemda | O19: pembelian | P19: 1.3821197e+08 | R19: sdn 1 derangga | S19: 1
A20: 9 | B20: Bangunan Gedung Pendidikan Permanen | C20: 03.01.01.10.001 | D20: 000006 | E20: Baik | F20: Tidak | G20: Beton | H20: 128 | I20: JL. H. Abu Hasan | J20: 44745 | K20: 027/696/DISDIK/SD/VII/2022 | O20: Pembelian | P20: 475405900 | Q20: Pembangunan Ruang Kelas Baru (RKB) beserta perabotnya SD NEGERI 1 DERANGGA DAK Fisik 2022 | R20: sdn 1 derangga | S20: 1
A21: 10 | B21: Bangunan Gedung Perpustakaan Permanen | C21: 03.01.01.16.001 | D21: 000001 | E21: Baik | F21: Tidak | G21: Tidak | H21: 61 | I21: Desa Derangga, Kecamatan Hanau | J21: 40413 | K21: 050/1656/Sek/VIII/2010 | M21: Tanah Milik Pemda | O21: Hibah | P21: 291315357 | Q21: 1 Unit Perpustakaan SDN - Derangga, Hanau, Seruyan | R21: sdn 1 derangga | S21: 1
A22: 11 | B22: Rumah Negara Golongan I Tipe E Permanen | C22: 03.01.02.01.013 | D22: 000001 | E22: Baik | F22: Tidak | G22: Tidak | H22: 60 | I22: Desa Derangga, Kecamatan Hanau | M22: Tanah Milik Pemda | O22: pembelian | P22: 77648000 | R22: sdn 1 derangga | S22: 1
A23: 12 | B23: Rumah Negara Golongan I Tipe E Permanen | C23: 03.01.02.01.013 | D23: 000002 | E23: Baik | F23: Tidak | G23: Tidak | H23: 60 | I23: Desa Derangga, Kecamatan Hanau | M23: Tanah Milik Pemda | O23: pembelian | P23: 77648000 | R23: sdn 1 derangga | S23: 1
A24: 13 | B24: Rumah Negara Golongan I Tipe E Permanen | C24: 03.01.02.01.013 | D24: 000003 | E24: Baik | F24: Tidak | G24: Tidak | H24: 60 | I24: Desa Derangga, Kecamatan Hanau | M24: Tanah Milik Pemda | O24: pembelian | P24: 77648000 | R24: sdn 1 derangga | S24: 1
A25: 14 | B25: Rumah Negara Golongan I Tipe E Permanen | C25: 03.01.02.01.013 | D25: 000004 | E25: Baik | F25: Tidak | G25: Tidak | H25: 60 | I25: Desa Derangga, Kecamatan Hanau | M25: Tanah Milik Pemda | O25: pembelian | P25: 77648000 | R25: sdn 1 derangga | S25: 1
A26: 15 | B26: Pagar Permanen | C26: 03.04.01.04.001 | D26: 000001 | E26: Baik | F26: Tidak | G26: Beton | H26: 73 | I26: Desa Derangga - Kecamatan Hanau | K26: 000.3.2/570/DISDIK/SD/VIII/2025 | O26: Pembelian | P26: 199284685 | Q26: Pekerjaan Pembangunan Pagar Keliling SDN 1 Desa Derangga | R26: sdn 1 derangga | S26: 1
